#VRML_SIM R2019a utf8
WorldInfo {
}
Viewpoint {
  orientation 0.385072720673567 0.7914078153699914 0.4747553786576353 4.307549196724354
  position -2.887736640045057 8.22936607154641 -0.5916803563589748
  follow "robot(1)"
  followOrientation TRUE
}
TexturedBackground {
}
TexturedBackgroundLight {
}
Floor {
}
DEF THREE_WHEELS Robot {
  translation 0.12311488900344691 0.0617682648129676 0.33324616831755083
  rotation 0.002836446067201989 0.9999956208298023 0.0008443310523704502 1.478339883780702
  children [
    DEF SOLID1 Solid {
      children [
        DEF WHEEL1 HingeJoint {
          jointParameters HingeJointParameters {
            position -538.6171111291133
            axis 0 0 1
            anchor 0 0 0.1
          }
          device [
            RotationalMotor {
              name "wheel1"
              maxVelocity 30.4
              maxTorque 0.847
            }
            PositionSensor {
              name "first_ps"
              resolution 0.00385
            }
          ]
          endPoint Solid {
            translation 0 0 0.15000000000000002
            rotation 0 0 1 1.736825288331182
            children [
              DEF sr1 HingeJoint {
                jointParameters HingeJointParameters {
                  position -5865.907284689421
                  anchor 0 0.05 0.02
                }
                endPoint Solid {
                  translation 0 0.05 0.02
                  rotation 1 0 0 2.5877922163123386
                  children [
                    DEF r1 Transform {
                      rotation 0 0 1 1.5708
                      children [
                        DEF SMALL_WHEEL_SHAPE Shape {
                          appearance PBRAppearance {
                            baseColor 0 0 0
                            roughness 1
                            metalness 0
                          }
                          geometry Cylinder {
                            height 0.02
                            radius 0.01
                          }
                        }
                      ]
                    }
                  ]
                  name "sr1"
                  boundingObject USE r1
                  physics Physics {
                    density -1
                    mass 0.1
                  }
                }
              }
              DEF sr2 HingeJoint {
                jointParameters HingeJointParameters {
                  position -3035.170628936447
                  axis 0.707107 0.707107 0
                  anchor -0.03535 0.03535 0.02
                }
                endPoint Solid {
                  translation -0.03535 0.03535 0.02
                  rotation 0.7071067811865475 0.7071067811865475 0 5.891059738472881
                  children [
                    DEF r2 Transform {
                      rotation 0 0 1 2.27
                      children [
                        USE SMALL_WHEEL_SHAPE
                      ]
                    }
                  ]
                  name "sr2"
                  boundingObject USE r2
                  physics Physics {
                    density -1
                    mass 0.1
                  }
                }
              }
              DEF sr3 HingeJoint {
                jointParameters HingeJointParameters {
                  position 10043.981936135557
                  anchor 0 -0.05 0.02
                }
                endPoint Solid {
                  translation 0 -0.05 0.02
                  rotation 1 0 0 3.45181526257749
                  children [
                    DEF r3 Transform {
                      rotation 0 0 1 1.5708
                      children [
                        USE SMALL_WHEEL_SHAPE
                      ]
                    }
                  ]
                  name "sr3"
                  boundingObject USE r3
                  physics Physics {
                    density -1
                    mass 0.1
                  }
                }
              }
              DEF sr4 HingeJoint {
                jointParameters HingeJointParameters {
                  position 5430.997211173655
                  axis 0.707107 0.707107 0
                  anchor 0.03535 -0.03535 0.02
                }
                endPoint Solid {
                  translation 0.03535 -0.03535 0.02
                  rotation 0.7071067811865477 0.7071067811865477 0 2.325105770492444
                  children [
                    DEF r4 Transform {
                      rotation 0 0 1 2.27
                      children [
                        USE SMALL_WHEEL_SHAPE
                      ]
                    }
                  ]
                  name "sr4"
                  boundingObject USE r4
                  physics Physics {
                    density -1
                    mass 0.1
                  }
                }
              }
              DEF sr5 HingeJoint {
                jointParameters HingeJointParameters {
                  position -5977.370064965878
                  axis 0 1 0
                  anchor -0.05 0 0.02
                }
                endPoint Solid {
                  translation -0.05 0 0.02
                  rotation 0 1 0 4.222347469088681
                  children [
                    DEF r5 Transform {
                      children [
                        USE SMALL_WHEEL_SHAPE
                      ]
                    }
                  ]
                  name "sr5"
                  boundingObject USE r5
                  physics Physics {
                    density -1
                    mass 0.1
                  }
                }
              }
              DEF sr6 HingeJoint {
                jointParameters HingeJointParameters {
                  position 7875.666952554395
                  axis 0 1 0
                  anchor 0.05 0 0.02
                }
                endPoint Solid {
                  translation 0.05 0 0.02
                  rotation 0 -1 0 3.447422648806631
                  children [
                    DEF r6 Transform {
                      children [
                        USE SMALL_WHEEL_SHAPE
                      ]
                    }
                  ]
                  name "sr6"
                  boundingObject USE r6
                  physics Physics {
                    density -1
                    mass 0.1
                  }
                }
              }
              DEF sr7 HingeJoint {
                jointParameters HingeJointParameters {
                  position -14116.584662473371
                  axis -0.707107 0.707107 0
                  anchor -0.03535 -0.03535 0.02
                }
                endPoint Solid {
                  translation -0.03535 -0.03535 0.02
                  rotation 0.7071067811865475 -0.7071067811865475 0 4.550462548020055
                  children [
                    DEF r7 Transform {
                      rotation 0 0 1 0.76
                      children [
                        USE SMALL_WHEEL_SHAPE
                      ]
                    }
                  ]
                  name "sr7"
                  boundingObject USE r7
                  physics Physics {
                    density -1
                    mass 0.1
                  }
                }
              }
              DEF sr8 HingeJoint {
                jointParameters HingeJointParameters {
                  position 7176.917959798022
                  axis -0.707107 0.707107 0
                  anchor 0.03535 0.03535 0.02
                }
                endPoint Solid {
                  translation 0.03535 0.03535 0.02
                  rotation -0.7071067811865476 0.7071067811865476 0 1.5203389989341547
                  children [
                    DEF r8 Transform {
                      rotation 0 0 1 0.76
                      children [
                        USE SMALL_WHEEL_SHAPE
                      ]
                    }
                  ]
                  name "sr8"
                  boundingObject USE r8
                  physics Physics {
                    density -1
                    mass 0.1
                  }
                }
              }
              DEF WHEEL_TRANS Transform {
                translation 0 0 0.02
                rotation 1 0 0 1.5708
                children [
                  DEF WHEEL_SHAPE Shape {
                    appearance PBRAppearance {
                      baseColor 0.5333333333333333 0.5411764705882353 0.5215686274509804
                      roughness 1
                      metalness 0
                    }
                    geometry Cylinder {
                      height 0.02
                      radius 0.05
                      subdivision 20
                    }
                  }
                ]
              }
            ]
            boundingObject Transform {
              translation 0 0 0.02
              rotation 1 0 0 1.5708
              children [
                DEF wheel1 Shape {
                  appearance PBRAppearance {
                    baseColor 0.8 0.8 0.8
                    transparency 0.12999999523162842
                    roughness 1
                    metalness 0
                    emissiveColor 0 1 0
                  }
                  geometry Cylinder {
                    height 0.02
                    radius 0.05
                  }
                }
              ]
            }
            physics Physics {
            }
          }
        }
      ]
      name "wheel 1"
      boundingObject DEF DUMMY Sphere {
        radius 0.01
      }
      physics Physics {
      }
    }
    DEF SOLID2 Solid {
      rotation 0 1 0 2.09
      children [
        DEF WHEEL2 HingeJoint {
          jointParameters HingeJointParameters {
            position 432.86451229999994
            axis 0 0 1
            anchor 0 0 0.1
          }
          device [
            RotationalMotor {
              name "wheel2"
              maxVelocity 30.4
              maxTorque 0.847
            }
            PositionSensor {
              name "second_ps"
              resolution 0.00385
            }
          ]
          endPoint Solid {
            translation 0 0 0.14999999999999997
            rotation 0 0 1 5.610317221783962
            children [
              DEF sr1 HingeJoint {
                jointParameters HingeJointParameters {
                  position -6661.384446102994
                  anchor 0 0.05 0.02
                }
                endPoint Solid {
                  translation 0 0.05 0.02
                  rotation -1 0 0 1.2080204926322682
                  children [
                    USE r1
                  ]
                  name "sr1"
                  boundingObject USE r1
                  physics Physics {
                    density -1
                    mass 0.1
                  }
                }
              }
              DEF sr2 HingeJoint {
                jointParameters HingeJointParameters {
                  position -4691.272216786455
                  axis 0.707107 0.707107 0
                  anchor -0.03535 0.03535 0.02
                }
                endPoint Solid {
                  translation -0.03535 0.03535 0.02
                  rotation -0.7071067811865475 -0.7071067811865475 0 4.015977630483407
                  children [
                    USE r2
                  ]
                  name "sr2"
                  boundingObject USE r2
                  physics Physics {
                    density -1
                    mass 0.1
                  }
                }
              }
              DEF sr3 HingeJoint {
                jointParameters HingeJointParameters {
                  position 3641.505609141215
                  anchor 0 -0.05 0.02
                }
                endPoint Solid {
                  translation 0 -0.05 0.02
                  rotation -0.9999999999999999 0 0 2.741869022945366
                  children [
                    USE r3
                  ]
                  name "sr3"
                  boundingObject USE r3
                  physics Physics {
                    density -1
                    mass 0.1
                  }
                }
              }
              DEF sr4 HingeJoint {
                jointParameters HingeJointParameters {
                  position 6792.566023894269
                  axis 0.707107 0.707107 0
                  anchor 0.03535 -0.03535 0.02
                }
                endPoint Solid {
                  translation 0.03535 -0.03535 0.02
                  rotation -0.7071067811865476 -0.7071067811865476 0 5.840478474043404
                  children [
                    USE r4
                  ]
                  name "sr4"
                  boundingObject USE r4
                  physics Physics {
                    density -1
                    mass 0.1
                  }
                }
              }
              DEF sr5 HingeJoint {
                jointParameters HingeJointParameters {
                  position -3291.111215436948
                  axis 0 1 0
                  anchor -0.05 0 0.02
                }
                endPoint Solid {
                  translation -0.05 0 0.02
                  rotation 0 0.9999999999999999 0 1.2778855251553272
                  children [
                    USE r5
                  ]
                  name "sr5"
                  boundingObject USE r5
                  physics Physics {
                    density -1
                    mass 0.1
                  }
                }
              }
              DEF sr6 HingeJoint {
                jointParameters HingeJointParameters {
                  position 12353.683821553768
                  axis 0 1 0
                  anchor 0.05 0 0.02
                }
                endPoint Solid {
                  translation 0.05 0 0.02
                  rotation 0 0.9999999999999999 0 0.9415076387011979
                  children [
                    USE r6
                  ]
                  name "sr6"
                  boundingObject USE r6
                  physics Physics {
                    density -1
                    mass 0.1
                  }
                }
              }
              DEF sr7 HingeJoint {
                jointParameters HingeJointParameters {
                  position -2393.0019522809894
                  axis -0.707107 0.707107 0
                  anchor -0.03535 -0.03535 0.02
                }
                endPoint Solid {
                  translation -0.03535 -0.03535 0.02
                  rotation 0.7071067811865476 -0.7071067811865476 0 5.39153555274651
                  children [
                    USE r7
                  ]
                  name "sr7"
                  boundingObject USE r7
                  physics Physics {
                    density -1
                    mass 0.1
                  }
                }
              }
              DEF sr8 HingeJoint {
                jointParameters HingeJointParameters {
                  position 10234.118140225719
                  axis -0.707107 0.707107 0
                  anchor 0.03535 0.03535 0.02
                }
                endPoint Solid {
                  translation 0.03535 0.03535 0.02
                  rotation -0.7071067811865476 0.7071067811865476 0 5.092460137352105
                  children [
                    USE r8
                  ]
                  name "sr8"
                  boundingObject USE r8
                  physics Physics {
                    density -1
                    mass 0.1
                  }
                }
              }
              USE WHEEL_TRANS
            ]
            boundingObject Transform {
              translation 0 0 0.02
              rotation 1 0 0 1.5708
              children [
                DEF wheel1 Shape {
                  appearance PBRAppearance {
                    baseColor 0.8 0.8 0.8
                    transparency 0.12999999523162842
                    roughness 1
                    metalness 0
                    emissiveColor 0 1 0
                  }
                  geometry Cylinder {
                    height 0.02
                    radius 0.05
                  }
                }
              ]
            }
            physics Physics {
            }
          }
        }
      ]
      name "wheel 2"
      boundingObject USE DUMMY
      physics Physics {
      }
    }
    DEF SOLID3 Solid {
      rotation 0 1 0 4.18
      children [
        DEF WHEEL3 HingeJoint {
          jointParameters HingeJointParameters {
            position 200.87250690277415
            axis 0 0 1
            anchor 0 0 0.1
          }
          device [
            RotationalMotor {
              name "wheel3"
              maxVelocity 30.4
              maxTorque 0.847
            }
            PositionSensor {
              name "third_ps"
              resolution 0.00385
            }
          ]
          endPoint Solid {
            translation 0 0 0.15000000000000002
            rotation 0 0 -1 0.1855134869731663
            children [
              DEF sr1 HingeJoint {
                jointParameters HingeJointParameters {
                  position 274.63898027302855
                  anchor 0 0.05 0.02
                }
                endPoint Solid {
                  translation 0 0.05 0.02
                  rotation -1 0 0 1.821173242873254
                  children [
                    USE r1
                  ]
                  name "sr1"
                  boundingObject USE r1
                  physics Physics {
                    density -1
                    mass 0.1
                  }
                }
              }
              DEF sr2 HingeJoint {
                jointParameters HingeJointParameters {
                  position 347.6578041138006
                  axis 0.707107 0.707107 0
                  anchor -0.03535 0.03535 0.02
                }
                endPoint Solid {
                  translation -0.03535 0.03535 0.02
                  rotation -0.7071067811865476 -0.7071067811865476 0 4.200573088256262
                  children [
                    USE r2
                  ]
                  name "sr2"
                  boundingObject USE r2
                  physics Physics {
                    density -1
                    mass 0.1
                  }
                }
              }
              DEF sr3 HingeJoint {
                jointParameters HingeJointParameters {
                  position 710.9179683235756
                  anchor 0 -0.05 0.02
                }
                endPoint Solid {
                  translation 0 -0.05 0.02
                  rotation -1 0 0 5.365156694897293
                  children [
                    USE r3
                  ]
                  name "sr3"
                  boundingObject USE r3
                  physics Physics {
                    density -1
                    mass 0.1
                  }
                }
              }
              DEF sr4 HingeJoint {
                jointParameters HingeJointParameters {
                  position -535.2861640474332
                  axis 0.707107 0.707107 0
                  anchor 0.03535 -0.03535 0.02
                }
                endPoint Solid {
                  translation 0.03535 -0.03535 0.02
                  rotation 0.7071067811865475 0.7071067811865475 0 5.067772370011234
                  children [
                    USE r4
                  ]
                  name "sr4"
                  boundingObject USE r4
                  physics Physics {
                    density -1
                    mass 0.1
                  }
                }
              }
              DEF sr5 HingeJoint {
                jointParameters HingeJointParameters {
                  position 467.91690452443646
                  axis 0 1 0
                  anchor -0.05 0 0.02
                }
                endPoint Solid {
                  translation -0.05 0 0.02
                  rotation 0 0.9999999999999999 0 2.9611917931470617
                  children [
                    USE r5
                  ]
                  name "sr5"
                  boundingObject USE r5
                  physics Physics {
                    density -1
                    mass 0.1
                  }
                }
              }
              DEF sr6 HingeJoint {
                jointParameters HingeJointParameters {
                  position -1601.6676247735854
                  axis 0 1 0
                  anchor 0.05 0 0.02
                }
                endPoint Solid {
                  translation 0.05 0 0.02
                  rotation 0 -1 0 5.738556749970465
                  children [
                    USE r6
                  ]
                  name "sr6"
                  boundingObject USE r6
                  physics Physics {
                    density -1
                    mass 0.1
                  }
                }
              }
              DEF sr7 HingeJoint {
                jointParameters HingeJointParameters {
                  position -208.46340793313348
                  axis -0.707107 0.707107 0
                  anchor -0.03535 -0.03535 0.02
                }
                endPoint Solid {
                  translation -0.03535 -0.03535 0.02
                  rotation -0.7071067811865475 0.7071067811865475 0 5.164892510972458
                  children [
                    USE r7
                  ]
                  name "sr7"
                  boundingObject USE r7
                  physics Physics {
                    density -1
                    mass 0.1
                  }
                }
              }
              DEF sr8 HingeJoint {
                jointParameters HingeJointParameters {
                  position -4131.868647844654
                  axis -0.707107 0.707107 0
                  anchor 0.03535 0.03535 0.02
                }
                endPoint Solid {
                  translation 0.03535 0.03535 0.02
                  rotation -0.7071067811865476 0.7071067811865476 0 2.4672842795135685
                  children [
                    USE r8
                  ]
                  name "sr8"
                  boundingObject USE r8
                  physics Physics {
                    density -1
                    mass 0.1
                  }
                }
              }
              USE WHEEL_TRANS
            ]
            boundingObject Transform {
              translation 0 0 0.02
              rotation 1 0 0 1.5708
              children [
                DEF wheel1 Shape {
                  appearance PBRAppearance {
                    baseColor 0.8 0.8 0.8
                    transparency 0.12999999523162842
                    roughness 1
                    metalness 0
                    emissiveColor 0 1 0
                  }
                  geometry Cylinder {
                    height 0.02
                    radius 0.05
                  }
                }
              ]
            }
            physics Physics {
            }
          }
        }
      ]
      name "wheel 3"
      boundingObject USE DUMMY
      physics Physics {
      }
    }
    DEF BODY_TRANS Transform {
      translation 0 -0.05 0
      scale 4 4 4
      children [
        Shape {
          appearance Appearance {
            material Material {
              ambientIntensity 1
              diffuseColor 0.792157 0.819608 0.933333
              shininess 0.4
              specularColor 0.396078 0.409804 0.466667
            }
            texture ImageTexture {
              url [
                "/home/jesus/Documents/Computational_Modeling/u3_real_exam_Duarte_Jesus/protos/anaranjado.png"
              ]
            }
          }
          geometry IndexedFaceSet {
            coord Coordinate {
              point [
                -0.043284 0.04 -0.009731, -0.043284 0.045 -0.009731, -0.043211 0.04 -0.013447, -0.043211 0.045 -0.013447, -0.04276 0.04 -0.006052, -0.04276 0.045 -0.006052, -0.042542 0.04 -0.017103, -0.042542 0.045 -0.017103, -0.041653 0.04 -0.002504, -0.041653 0.045 -0.002504, -0.041297 0.04 -0.010023, -0.041297 0.045 -0.010023, -0.041296 0.04 -0.020604, -0.041296 0.045 -0.020604, -0.041208 0.04 -0.013368, -0.041208 0.045 -0.013368, -0.040857 0.04 -0.006705, -0.040857 0.045 -0.006705, -0.040591 0.04 -0.016656, -0.040591 0.045 -0.016656, -0.039992 0 0.000821, -0.039992 0.04 0.000821, -0.039992 0.045 0.000821, -0.039897 0.04 -0.0035, -0.039897 0.045 -0.0035, -0.039504 0.04 -0.02386, -0.039504 0.045 -0.02386, -0.039462 0.04 -0.019806, -0.039462 0.045 -0.019806, -0.037848 0.04 -0.022738, -0.037848 0.045 -0.022738, -0.037213 0.04 -0.026787, -0.037213 0.045 -0.026787, -0.035792 0.04 -0.025378, -0.035792 0.045 -0.025378, -0.034482 0.04 -0.029308, -0.034482 0.045 -0.029308, -0.033344 0.04 -0.027659, -0.033344 0.045 -0.027659, -0.031382 0.04 -0.031358, -0.031382 0.045 -0.031358, -0.030566 0.04 -0.029524, -0.030566 0.045 -0.029524, -0.027994 0.04 -0.032885, -0.027994 0.045 -0.032885, -0.027527 0.04 -0.030927, -0.027527 0.045 -0.030927, -0.024404 0.04 -0.033848, -0.024404 0.045 -0.033848, -0.024306 0.04 -0.031831, -0.024306 0.045 -0.031831, -0.020707 0 -0.034223, -0.020707 0.04 -0.034223, -0.020707 0.045 -0.034223, -0.019285 0 0.035044, -0.019285 0.04 0.035044, -0.019285 0.045 0.035044, -0.017111 0.04 0.038059, -0.017111 0.045 0.038059, -0.014482 0.04 0.040686, -0.014482 0.045 0.040686, -0.013087 0.04 0.037918, -0.013087 0.045 0.037918, -0.011466 0.04 0.042857, -0.011466 0.045 0.042857, -0.010396 0.04 0.039989, -0.010396 0.045 0.039989, -0.00814 0.04 0.044516, -0.00814 0.045 0.044516, -0.007396 0.04 0.041578, -0.007396 0.045 0.041578, -0.004592 0.04 0.045621, -0.004592 0.045 0.045621, -0.004171 0.04 0.042639, -0.004171 0.045 0.042639, -0.000912 0.04 0.046142, -0.000912 0.045 0.046142, -0.000813 0.04 0.043142, -0.000813 0.045 0.043142, 0.002582 0.04 0.043072, 0.002582 0.045 0.043072, 0.002804 0.04 0.046065, 0.002804 0.045 0.046065, 0.005916 0.04 0.042432, 0.005916 0.045 0.042432, 0.00646 0.04 0.045394, 0.00646 0.045 0.045394, 0.009096 0.04 0.04124, 0.009096 0.045 0.04124, 0.00996 0.04 0.044145, 0.00996 0.045 0.044145, 0.012028 0.04 0.039529, 0.012028 0.045 0.039529, 0.013215 0.04 0.042351, 0.013215 0.045 0.042351, 0.014631 0.04 0.037349, 0.014631 0.045 0.037349, 0.016139 0.04 0.040057, 0.016139 0.045 0.040057, 0.018659 0.04 0.037325, 0.018659 0.045 0.037325, 0.019285 0 -0.035044, 0.019285 0.04 -0.035044, 0.019285 0.045 -0.035044, 0.020707 0 0.034223, 0.020707 0.04 0.034223, 0.020707 0.045 0.034223, 0.022979 0.04 -0.032802, 0.022979 0.045 -0.032802, 0.022995 0.04 -0.034821, 0.022995 0.045 -0.034821, 0.026235 0.04 -0.03203, 0.026235 0.045 -0.03203, 0.026621 0.04 -0.034006, 0.026621 0.045 -0.034006, 0.029328 0.04 -0.030753, 0.029328 0.045 -0.030753, 0.030069 0.04 -0.03262, 0.030069 0.045 -0.03262, 0.032181 0.04 -0.029004, 0.032181 0.045 -0.029004, 0.033251 0.04 -0.030698, 0.033251 0.045 -0.030698, 0.03472 0.04 -0.026825, 0.03472 0.045 -0.026825, 0.036083 0.04 -0.028291, 0.036083 0.045 -0.028291, 0.036884 0.04 -0.024272, 0.036884 0.045 -0.024272, 0.038492 0.04 -0.025461, 0.038492 0.045 -0.025461, 0.038616 0.04 -0.021409, 0.038616 0.045 -0.021409, 0.03972 0.04 -0.005134, 0.03972 0.045 -0.005134, 0.039874 0.04 -0.018308, 0.039874 0.045 -0.018308, 0.039992 0 -0.000821, 0.039992 0.04 -0.000821, 0.039992 0.045 -0.000821, 0.040416 0.04 -0.022281, 0.040416 0.045 -0.022281, 0.040547 0.04 -0.008376, 0.040547 0.045 -0.008376, 0.040625 0.04 -0.015047, 0.040625 0.045 -0.015047, 0.040851 0.04 -0.011708, 0.040851 0.045 -0.011708, 0.041516 0.04 -0.00421, 0.041516 0.045 -0.00421, 0.041805 0.04 -0.018834, 0.041805 0.045 -0.018834, 0.042476 0.04 -0.007801, 0.042476 0.045 -0.007801, 0.042623 0.04 -0.015208, 0.042623 0.045 -0.015208, 0.042848 0.04 -0.011499, 0.042848 0.045 -0.011499
              ]
            }
            coordIndex [
              53, 103, 52, -1, 52, 103, 102, -1, 52, 102, 51, -1, 51, 102, 101, -1, 21, 52, 20, -1, 20, 52, 51, -1, 20, 54, 21, -1, 21, 54, 55, -1, 21, 55, 22, -1, 22, 55, 56, -1, 105, 55, 104, -1, 104, 55, 54, -1, 104, 137, 105, -1, 105, 137, 138, -1, 105, 138, 106, -1, 106, 138, 139, -1, 102, 138, 101, -1, 101, 138, 137, -1, 137, 104, 101, -1, 101, 104, 54, -1, 101, 54, 51, -1, 51, 54, 20, -1, 45, 47, 49, -1, 49, 47, 52, -1, 49, 52, 23, -1, 52, 21, 23, -1, 23, 21, 8, -1, 23, 8, 16, -1, 16, 8, 4, -1, 16, 4, 10, -1, 10, 4, 0, -1, 10, 0, 14, -1, 14, 0, 2, -1, 14, 2, 18, -1, 18, 2, 6, -1, 18, 6, 27, -1, 27, 6, 12, -1, 27, 12, 29, -1, 29, 12, 25, -1, 29, 25, 33, -1, 33, 25, 31, -1, 33, 31, 37, -1, 37, 31, 35, -1, 37, 35, 41, -1, 41, 35, 39, -1, 41, 39, 45, -1, 45, 39, 43, -1, 45, 43, 47, -1, 105, 95, 55, -1, 55, 95, 61, -1, 55, 61, 57, -1, 105, 99, 95, -1, 95, 99, 97, -1, 95, 97, 91, -1, 91, 97, 93, -1, 91, 93, 87, -1, 87, 93, 89, -1, 87, 89, 83, -1, 83, 89, 85, -1, 83, 85, 79, -1, 79, 85, 81, -1, 79, 81, 77, -1, 77, 81, 75, -1, 77, 75, 73, -1, 73, 75, 71, -1, 73, 71, 69, -1, 69, 71, 67, -1, 69, 67, 65, -1, 65, 67, 63, -1, 65, 63, 61, -1, 61, 63, 59, -1, 61, 59, 57, -1, 53, 52, 47, -1, 53, 47, 48, -1, 48, 47, 43, -1, 48, 43, 44, -1, 44, 43, 39, -1, 44, 39, 40, -1, 40, 39, 35, -1, 40, 35, 36, -1, 36, 35, 31, -1, 36, 31, 32, -1, 32, 31, 25, -1, 32, 25, 26, -1, 26, 25, 12, -1, 26, 12, 13, -1, 13, 12, 6, -1, 13, 6, 7, -1, 7, 6, 2, -1, 7, 2, 3, -1, 3, 2, 0, -1, 3, 0, 1, -1, 1, 0, 4, -1, 1, 4, 5, -1, 5, 4, 8, -1, 5, 8, 9, -1, 9, 8, 21, -1, 9, 21, 22, -1, 56, 55, 57, -1, 56, 57, 58, -1, 58, 57, 59, -1, 58, 59, 60, -1, 60, 59, 63, -1, 60, 63, 64, -1, 64, 63, 67, -1, 64, 67, 68, -1, 68, 67, 71, -1, 68, 71, 72, -1, 72, 71, 75, -1, 72, 75, 76, -1, 76, 75, 81, -1, 76, 81, 82, -1, 82, 81, 85, -1, 82, 85, 86, -1, 86, 85, 89, -1, 86, 89, 90, -1, 90, 89, 93, -1, 90, 93, 94, -1, 94, 93, 97, -1, 94, 97, 98, -1, 98, 97, 99, -1, 98, 99, 100, -1, 100, 99, 105, -1, 100, 105, 106, -1, 139, 138, 148, -1, 139, 148, 149, -1, 149, 148, 152, -1, 149, 152, 153, -1, 153, 152, 156, -1, 153, 156, 157, -1, 157, 156, 154, -1, 157, 154, 155, -1, 155, 154, 150, -1, 155, 150, 151, -1, 151, 150, 140, -1, 151, 140, 141, -1, 141, 140, 129, -1, 141, 129, 130, -1, 130, 129, 125, -1, 130, 125, 126, -1, 126, 125, 121, -1, 126, 121, 122, -1, 122, 121, 117, -1, 122, 117, 118, -1, 118, 117, 113, -1, 118, 113, 114, -1, 114, 113, 109, -1, 114, 109, 110, -1, 110, 109, 102, -1, 110, 102, 103, -1, 9, 24, 17, -1, 62, 50, 24, -1, 103, 108, 110, -1, 110, 108, 112, -1, 62, 60, 66, -1, 66, 60, 64, -1, 66, 64, 70, -1, 70, 64, 68, -1, 70, 68, 74, -1, 74, 68, 72, -1, 74, 72, 78, -1, 78, 72, 76, -1, 78, 76, 80, -1, 80, 76, 82, -1, 80, 82, 84, -1, 84, 82, 86, -1, 84, 86, 88, -1, 88, 86, 90, -1, 88, 90, 92, -1, 92, 90, 94, -1, 92, 94, 96, -1, 96, 94, 98, -1, 96, 98, 100, -1, 9, 22, 24, -1, 24, 22, 56, -1, 24, 56, 62, -1, 62, 56, 58, -1, 62, 58, 60, -1, 134, 108, 96, -1, 96, 108, 103, -1, 96, 103, 62, -1, 62, 103, 53, -1, 62, 53, 50, -1, 50, 53, 48, -1, 50, 48, 46, -1, 46, 48, 44, -1, 46, 44, 42, -1, 42, 44, 40, -1, 42, 40, 38, -1, 38, 40, 36, -1, 38, 36, 34, -1, 34, 36, 32, -1, 34, 32, 30, -1, 30, 32, 26, -1, 30, 26, 28, -1, 28, 26, 13, -1, 28, 13, 19, -1, 19, 13, 7, -1, 19, 7, 15, -1, 15, 7, 3, -1, 15, 3, 11, -1, 11, 3, 1, -1, 11, 1, 17, -1, 17, 1, 5, -1, 17, 5, 9, -1, 100, 106, 96, -1, 96, 106, 139, -1, 96, 139, 134, -1, 134, 139, 149, -1, 134, 149, 143, -1, 143, 149, 153, -1, 143, 153, 147, -1, 147, 153, 157, -1, 147, 157, 145, -1, 145, 157, 155, -1, 145, 155, 136, -1, 136, 155, 151, -1, 136, 151, 132, -1, 132, 151, 141, -1, 132, 141, 128, -1, 128, 141, 130, -1, 128, 130, 124, -1, 124, 130, 126, -1, 124, 126, 120, -1, 120, 126, 122, -1, 120, 122, 116, -1, 116, 122, 118, -1, 116, 118, 112, -1, 112, 118, 114, -1, 112, 114, 110, -1, 142, 148, 133, -1, 133, 148, 138, -1, 133, 138, 107, -1, 138, 102, 107, -1, 107, 102, 109, -1, 107, 109, 111, -1, 111, 109, 113, -1, 111, 113, 115, -1, 115, 113, 117, -1, 115, 117, 119, -1, 119, 117, 121, -1, 119, 121, 123, -1, 123, 121, 125, -1, 123, 125, 127, -1, 127, 125, 129, -1, 127, 129, 131, -1, 131, 129, 140, -1, 131, 140, 135, -1, 135, 140, 150, -1, 135, 150, 144, -1, 144, 150, 154, -1, 144, 154, 146, -1, 146, 154, 156, -1, 146, 156, 142, -1, 142, 156, 152, -1, 142, 152, 148, -1, 96, 95, 92, -1, 92, 95, 91, -1, 92, 91, 88, -1, 88, 91, 87, -1, 88, 87, 84, -1, 84, 87, 83, -1, 84, 83, 80, -1, 80, 83, 79, -1, 80, 79, 78, -1, 78, 79, 77, -1, 78, 77, 74, -1, 74, 77, 73, -1, 74, 73, 70, -1, 70, 73, 69, -1, 70, 69, 66, -1, 66, 69, 65, -1, 66, 65, 62, -1, 62, 65, 61, -1, 61, 95, 62, -1, 62, 95, 96, -1, 108, 107, 112, -1, 112, 107, 111, -1, 112, 111, 116, -1, 116, 111, 115, -1, 116, 115, 120, -1, 120, 115, 119, -1, 120, 119, 124, -1, 124, 119, 123, -1, 124, 123, 128, -1, 128, 123, 127, -1, 128, 127, 132, -1, 132, 127, 131, -1, 132, 131, 136, -1, 136, 131, 135, -1, 136, 135, 145, -1, 145, 135, 144, -1, 145, 144, 147, -1, 147, 144, 146, -1, 147, 146, 143, -1, 143, 146, 142, -1, 143, 142, 134, -1, 134, 142, 133, -1, 133, 107, 134, -1, 134, 107, 108, -1, 24, 23, 17, -1, 17, 23, 16, -1, 17, 16, 11, -1, 11, 16, 10, -1, 11, 10, 15, -1, 15, 10, 14, -1, 15, 14, 19, -1, 19, 14, 18, -1, 19, 18, 28, -1, 28, 18, 27, -1, 28, 27, 30, -1, 30, 27, 29, -1, 30, 29, 34, -1, 34, 29, 33, -1, 34, 33, 38, -1, 38, 33, 37, -1, 38, 37, 42, -1, 42, 37, 41, -1, 42, 41, 46, -1, 46, 41, 45, -1, 46, 45, 50, -1, 50, 45, 49, -1, 49, 23, 50, -1, 50, 23, 24, -1
            ]
          }
        }
      ]
    }
    DEF left DistanceSensor {
      translation 0.15 0.04 0
      name "left_light"
      lookupTable [
        0 0 0
        0.05 0 0
        0.4 255 0
      ]
    }
    DEF right DistanceSensor {
      translation 0.1 0.04 0.1
      rotation 0 1 0 -0.9162996938995747
      name "right_light"
      lookupTable [
        0 0 0
        0.05 0 0
        0.4 255 0
      ]
    }
    DEF Post_Transform Transform {
      translation 0 0.17 0
      children [
        DEF Radar HingeJoint {
          jointParameters HingeJointParameters {
            position 1181.0161271559666
            axis 0 1 0
          }
          device [
            RotationalMotor {
              name "detector_motor"
              maxVelocity 30.4
              maxTorque 0.847
            }
            PositionSensor {
              name "detector_sensor"
              resolution 0.003848
            }
          ]
          endPoint Solid {
            rotation 0 -1 0 0.22271059379564354
            children [
              DEF Post Transform {
                children [
                  DEF Post Shape {
                    appearance PBRAppearance {
                      baseColor 0.20392156862745098 0.396078431372549 0.6431372549019608
                      roughness 1
                      metalness 0
                    }
                    geometry Cylinder {
                      height 0.08
                      radius 0.019999999999999997
                    }
                  }
                  DEF Detector Transform {
                    translation 0.01 0.03 0
                    rotation 0 0 1 1.57
                    children [
                      Shape {
                        appearance PBRAppearance {
                          baseColor 0.8 0 0
                          roughness 1
                          metalness 0
                        }
                        geometry Cylinder {
                          height 0.05
                          radius 0.005
                        }
                      }
                      DistanceSensor {
                        rotation 0 0 1 -1.57
                        name "detector_distance"
                        lookupTable [
                          0 0 0
                          0.05 0 0
                          0.4 255 0
                        ]
                      }
                    ]
                  }
                ]
              }
            ]
            boundingObject USE Post
            physics Physics {
            }
          }
        }
        DEF Gun HingeJoint {
          jointParameters HingeJointParameters {
            position 4.3363776206970215
            axis 0 1 0
          }
          device [
            RotationalMotor {
              name "gun_motor"
              maxVelocity 30.4
              maxTorque 0.847
            }
            PositionSensor {
              name "gun_sensor"
              resolution 0.003848
            }
          ]
          endPoint Solid {
            rotation 0 0.9999999999999999 0 4.3363776206970215
            children [
              DEF GUN Transform {
                translation 0.01 0 0
                rotation 0 0 1 1.5707996938995747
                children [
                  DEF GUN Shape {
                    appearance PBRAppearance {
                      baseColor 0.4588235294117647 0.3137254901960784 0.4823529411764706
                      roughness 1
                      metalness 0
                    }
                    geometry Cylinder {
                      height 0.05
                      radius 0.005
                    }
                  }
                  DistanceSensor {
                    rotation 0 0 1 -1.5707996938995747
                    name "gun_distance"
                    lookupTable [
                      0 0 0
                      0.05 0 0
                      0.4 255 0
                    ]
                  }
                ]
              }
            ]
            name "solid(1)"
            boundingObject USE GUN
            physics Physics {
            }
          }
        }
      ]
    }
  ]
  name "robot(1)"
  boundingObject USE BODY_TRANS
  physics Physics {
  }
  controller "u3_real_exam"
}
DEF wall Solid {
  translation 2.9130285231827795 0.1 -1.795343700466084
  rotation 0 1 0 6.283185277377264
  children [
    DEF wall Shape {
      appearance PBRAppearance {
      }
      geometry Box {
        size 2.9 0.2 0.30000000000000004
      }
    }
  ]
  name "solid(1)"
  boundingObject USE wall
}
DEF wall Solid {
  translation 0.017799258150501984 0.10000000450325765 -1.7976897113958457
  rotation -3.3306690738754696e-16 3.7230319952779894e-09 -1 3.14159268137888
  children [
    DEF wall Shape {
      appearance PBRAppearance {
      }
      geometry Box {
        size 2.9 0.2 0.30000000000000004
      }
    }
  ]
  name "solid(3)"
  boundingObject USE wall
}
DEF wall Solid {
  translation 2.9374308061786243 0.09999998940970797 1.3848440295065862
  rotation 0.4319751934653309 0.8944271747405889 0.11574740306442358 6.2831852650327376
  children [
    DEF wall Shape {
      appearance PBRAppearance {
      }
      geometry Box {
        size 2.9 0.2 0.30000000000000004
      }
    }
  ]
  name "solid(2)"
  boundingObject USE wall
}
DEF wall Solid {
  translation 4.214887571329155 0.1 -0.16806433571955157
  rotation -6.781008137574549e-09 1 -1.174505074707215e-08 1.570796302820415
  children [
    DEF wall Shape {
      appearance PBRAppearance {
      }
      geometry Box {
        size 2.9 0.2 0.30000000000000004
      }
    }
  ]
  name "solid(6)"
  boundingObject USE wall
}
DEF wall Solid {
  translation -1.5963397685899179 0.0999999911535684 -0.22993082030833642
  rotation -1.1745050198999062e-08 -0.9999999999999999 6.7810080464096115e-09 1.5707963795387576
  children [
    DEF wall Shape {
      appearance PBRAppearance {
      }
      geometry Box {
        size 3.4 0.2 0.30000000000000004
      }
    }
  ]
  name "solid(5)"
  boundingObject USE wall
}
DEF wall Solid {
  translation 0.029956354467783927 0.09999997963985487 1.396079798323054
  rotation 2.4820212527885835e-09 1 -9.263029337235707e-09 3.1415926248204156
  children [
    DEF wall Shape {
      appearance PBRAppearance {
      }
      geometry Box {
        size 2.9 0.2 0.30000000000000004
      }
    }
  ]
  name "solid(4)"
  boundingObject USE wall
}
DEF Enemy_ Solid {
  translation 3.6399999999999966 0.3300000000000001 -1.2700000000000005
  children [
    DEF ENEMY Shape {
      appearance PBRAppearance {
        baseColor 0.8 0 0
      }
      geometry Box {
        size 0.2 0.2 0.2
      }
    }
  ]
  boundingObject USE ENEMY
}
DEF obstacle_ Solid {
  translation 1.790000085188585 0.0968608004057422 0.21000008518858296
  rotation -0.0006014604378086034 4.27577696410847e-09 0.9999998191226545 6.283185307179586
  children [
    Shape {
      appearance PBRAppearance {
        baseColor 0.12549019607843137 0.2901960784313726 0.5294117647058824
      }
      geometry DEF osbstacle Box {
        size 0.2 0.2 0.2
      }
    }
  ]
  name "solid(7)"
  boundingObject USE osbstacle
  physics Physics {
  }
}
