#VRML_SIM R2019a utf8
WorldInfo {
}
Viewpoint {
  orientation 0.005603870581953098 -0.9106379397573879 -0.41316720502590765 3.1444326815602026
  position 1.2963907659110339 6.0288852714418795 -6.603583924019583
}
TexturedBackground {
}
TexturedBackgroundLight {
}
Floor {
}
DEF THREE_WHEELS Robot {
  translation 3.94950769041912 0.055199959244916656 -0.37667041863921535
  rotation -0.00036934351174742856 -0.9999957544819862 -0.002890433077198722 -1.1568465422432743
  children [
    DEF SOLID1 Solid {
      children [
        DEF WHEEL1 HingeJoint {
          jointParameters HingeJointParameters {
            position -510.09554747555995
            axis 0 0 1
            anchor 0 0 0.1
          }
          device [
            RotationalMotor {
              name "wheel1"
              maxVelocity 30.4
              maxTorque 0.847
            }
            PositionSensor {
              name "first_ps"
              resolution 0.00385
            }
          ]
          endPoint Solid {
            translation 0 0 0.15000000000000002
            rotation 0 0 1 5.1256477131661375
            children [
              DEF sr1 HingeJoint {
                jointParameters HingeJointParameters {
                  position -5534.615189823107
                  anchor 0 0.05 0.02
                }
                endPoint Solid {
                  translation 0 0.05 0.02
                  rotation -1 0 0 5.412119505071257
                  children [
                    DEF r1 Transform {
                      rotation 0 0 1 1.5708
                      children [
                        DEF SMALL_WHEEL_SHAPE Shape {
                          appearance PBRAppearance {
                            baseColor 0 0 0
                            roughness 1
                            metalness 0
                          }
                          geometry Cylinder {
                            height 0.02
                            radius 0.01
                          }
                        }
                      ]
                    }
                  ]
                  name "sr1"
                  boundingObject USE r1
                  physics Physics {
                    density -1
                    mass 0.1
                  }
                  linearVelocity 0.07780216751303884 -0.0882068255395223 -0.16624448892510932
                  angularVelocity -3.626215980258535 5.591938803394766 3.0456215271619085
                }
              }
              DEF sr2 HingeJoint {
                jointParameters HingeJointParameters {
                  position -2719.0982001298444
                  axis 0.707107 0.707107 0
                  anchor -0.03535 0.03535 0.02
                }
                endPoint Solid {
                  translation -0.03535 0.03535 0.02
                  rotation -0.7071067811865475 -0.7071067811865475 0 4.762147428263014
                  children [
                    DEF r2 Transform {
                      rotation 0 0 1 2.27
                      children [
                        USE SMALL_WHEEL_SHAPE
                      ]
                    }
                  ]
                  name "sr2"
                  boundingObject USE r2
                  physics Physics {
                    density -1
                    mass 0.1
                  }
                  linearVelocity 0.09995960918785665 -0.02070761872009559 -0.19707183489806204
                  angularVelocity 1.776371209824235 -0.7772498057905832 -9.044737028917002
                }
              }
              DEF sr3 HingeJoint {
                jointParameters HingeJointParameters {
                  position 3632.7041294032692
                  anchor 0 -0.05 0.02
                }
                endPoint Solid {
                  translation 0 -0.05 0.02
                  rotation 0.9999999999999999 0 0 1.0230218534682511
                  children [
                    DEF r3 Transform {
                      rotation 0 0 1 1.5708
                      children [
                        USE SMALL_WHEEL_SHAPE
                      ]
                    }
                  ]
                  name "sr3"
                  boundingObject USE r3
                  physics Physics {
                    density -1
                    mass 0.1
                  }
                  linearVelocity 0.03918341914221426 0.0691103381081199 -0.04581398205491925
                  angularVelocity 0.740030542064988 -7.746200185686934 -6.703238034977646
                }
              }
              DEF sr4 HingeJoint {
                jointParameters HingeJointParameters {
                  position 5292.398577916825
                  axis 0.707107 0.707107 0
                  anchor 0.03535 -0.03535 0.02
                }
                endPoint Solid {
                  translation 0.03535 -0.03535 0.02
                  rotation 0.7071067811865476 0.7071067811865476 0 1.9565492716133475
                  children [
                    DEF r4 Transform {
                      rotation 0 0 1 2.27
                      children [
                        USE SMALL_WHEEL_SHAPE
                      ]
                    }
                  ]
                  name "sr4"
                  boundingObject USE r4
                  physics Physics {
                    density -1
                    mass 0.1
                  }
                  linearVelocity 0.01704436355781221 0.001571732315673439 -0.014990300046732942
                  angularVelocity -1.5064833493933558 0.11374773176752762 -1.5650926747629215
                }
              }
              DEF sr5 HingeJoint {
                jointParameters HingeJointParameters {
                  position -5588.972495983261
                  axis 0 1 0
                  anchor -0.05 0 0.02
                }
                endPoint Solid {
                  translation -0.05 0 0.02
                  rotation 0 0.9999999999999999 0 3.062427406570895
                  children [
                    DEF r5 Transform {
                      children [
                        USE SMALL_WHEEL_SHAPE
                      ]
                    }
                  ]
                  name "sr5"
                  boundingObject USE r5
                  physics Physics {
                    density -1
                    mass 0.1
                  }
                  linearVelocity 0.09783525998998337 0.053327537212843196 -0.17458721756788304
                  angularVelocity -3.279254723386343 -2.6003776477124814 2.362974609787353
                }
              }
              DEF sr6 HingeJoint {
                jointParameters HingeJointParameters {
                  position 7769.081235740678
                  axis 0 1 0
                  anchor 0.05 0 0.02
                }
                endPoint Solid {
                  translation 0.05 0 0.02
                  rotation 0 1 0 3.064196066708699
                  children [
                    DEF r6 Transform {
                      children [
                        USE SMALL_WHEEL_SHAPE
                      ]
                    }
                  ]
                  name "sr6"
                  boundingObject USE r6
                  physics Physics {
                    density -1
                    mass 0.1
                  }
                  linearVelocity 0.019150505484616345 -0.07241950984225973 -0.037471627133379884
                  angularVelocity -0.00785765300440866 3.8324509647657288 -5.023253558954176
                }
              }
              DEF sr7 HingeJoint {
                jointParameters HingeJointParameters {
                  position -3157.6952499287977
                  axis -0.707107 0.707107 0
                  anchor -0.03535 -0.03535 0.02
                }
                endPoint Solid {
                  translation -0.03535 -0.03535 0.02
                  rotation 0.7071067811865476 -0.7071067811865476 0 3.536225724645282
                  children [
                    DEF r7 Transform {
                      rotation 0 0 1 0.76
                      children [
                        USE SMALL_WHEEL_SHAPE
                      ]
                    }
                  ]
                  name "sr7"
                  boundingObject USE r7
                  physics Physics {
                    density -1
                    mass 0.1
                  }
                  linearVelocity 0.0724936204781706 0.09049831649240248 -0.11201734334599939
                  angularVelocity -2.336069220614597 -11.435300161129451 0.28652796927606816
                }
              }
              DEF sr8 HingeJoint {
                jointParameters HingeJointParameters {
                  position 6916.303852257378
                  axis -0.707107 0.707107 0
                  anchor 0.03535 0.03535 0.02
                }
                endPoint Solid {
                  translation 0.03535 0.03535 0.02
                  rotation -0.7071067811865476 0.7071067811865476 0 4.800014359832788
                  children [
                    DEF r8 Transform {
                      rotation 0 0 1 0.76
                      children [
                        USE SMALL_WHEEL_SHAPE
                      ]
                    }
                  ]
                  name "sr8"
                  boundingObject USE r8
                  physics Physics {
                    density -1
                    mass 0.1
                  }
                  linearVelocity 0.04432948664987143 -0.10961078068746104 -0.10013111300320332
                  angularVelocity -1.5992806861063005 6.019456246196658 -1.4742387139857567
                }
              }
              DEF WHEEL_TRANS Transform {
                translation 0 0 0.02
                rotation 1 0 0 1.5708
                children [
                  DEF WHEEL_SHAPE Shape {
                    appearance PBRAppearance {
                      baseColor 0.5333333333333333 0.5411764705882353 0.5215686274509804
                      roughness 1
                      metalness 0
                    }
                    geometry Cylinder {
                      height 0.02
                      radius 0.05
                      subdivision 20
                    }
                  }
                ]
              }
            ]
            boundingObject Transform {
              translation 0 0 0.02
              rotation 1 0 0 1.5708
              children [
                DEF wheel1 Shape {
                  appearance PBRAppearance {
                    baseColor 0.8 0.8 0.8
                    transparency 0.12999999523162842
                    roughness 1
                    metalness 0
                    emissiveColor 0 1 0
                  }
                  geometry Cylinder {
                    height 0.02
                    radius 0.05
                  }
                }
              ]
            }
            physics Physics {
            }
            linearVelocity 0.05849304478355615 -0.009546228846357918 -0.10603029591094834
            angularVelocity -1.8221484331039624 0.20771529875240843 -0.854841054897635
          }
        }
      ]
      name "wheel 1"
      boundingObject DEF DUMMY Sphere {
        radius 0.01
      }
      physics Physics {
      }
    }
    DEF SOLID2 Solid {
      rotation 0 1 0 2.09
      children [
        DEF WHEEL2 HingeJoint {
          jointParameters HingeJointParameters {
            position 433.6294673163466
            axis 0 0 1
            anchor 0 0 0.1
          }
          device [
            RotationalMotor {
              name "wheel2"
              maxVelocity 30.4
              maxTorque 0.847
            }
            PositionSensor {
              name "second_ps"
              resolution 0.00385
            }
          ]
          endPoint Solid {
            translation 0 0 0.14999999999999997
            rotation 0 0 -1 6.191098376225395
            children [
              DEF sr1 HingeJoint {
                jointParameters HingeJointParameters {
                  position -6257.366056004278
                  anchor 0 0.05 0.02
                }
                endPoint Solid {
                  translation 0 0.05 0.02
                  rotation 1 0 0 0.686509946590024
                  children [
                    USE r1
                  ]
                  name "sr1"
                  boundingObject USE r1
                  physics Physics {
                    density -1
                    mass 0.1
                  }
                  linearVelocity 0.020369194827542746 0.0038176187506251866 -0.06750477623268432
                  angularVelocity 20.685009612241856 3.3930787174100283 -2.332383877196941
                }
              }
              DEF sr2 HingeJoint {
                jointParameters HingeJointParameters {
                  position -4521.801772120983
                  axis 0.707107 0.707107 0
                  anchor -0.03535 0.03535 0.02
                }
                endPoint Solid {
                  translation -0.03535 0.03535 0.02
                  rotation 0.7071067811865475 0.7071067811865475 0 2.0916490483196584
                  children [
                    USE r2
                  ]
                  name "sr2"
                  boundingObject USE r2
                  physics Physics {
                    density -1
                    mass 0.1
                  }
                  linearVelocity 0.017234155105182933 -0.0054458650768563505 -0.07542957041016132
                  angularVelocity -4.237666036625938 3.3595491815624365 0.16356226571115795
                }
              }
              DEF sr3 HingeJoint {
                jointParameters HingeJointParameters {
                  position 2986.377366511321
                  anchor 0 -0.05 0.02
                }
                endPoint Solid {
                  translation 0 -0.05 0.02
                  rotation -1 0 0 4.4188397061623474
                  children [
                    USE r3
                  ]
                  name "sr3"
                  boundingObject USE r3
                  physics Physics {
                    density -1
                    mass 0.1
                  }
                  linearVelocity -0.004829110078153746 0.00019087718329266853 -0.0712496708451971
                  angularVelocity -7.292827031897418 -0.8983663341726696 0.46442625119511705
                }
              }
              DEF sr4 HingeJoint {
                jointParameters HingeJointParameters {
                  position 6623.715779043808
                  axis 0.707107 0.707107 0
                  anchor 0.03535 -0.03535 0.02
                }
                endPoint Solid {
                  translation 0.03535 -0.03535 0.02
                  rotation 0.7071067811865475 0.7071067811865475 0 1.238465276523596
                  children [
                    USE r4
                  ]
                  name "sr4"
                  boundingObject USE r4
                  physics Physics {
                    density -1
                    mass 0.1
                  }
                  linearVelocity -0.0017098665101064167 0.009441345794371064 -0.06332310694717254
                  angularVelocity -0.7309841792508428 0.7558960697978917 -0.18009460935446855
                }
              }
              DEF sr5 HingeJoint {
                jointParameters HingeJointParameters {
                  position -2982.4015629763167
                  axis 0 1 0
                  anchor -0.05 0 0.02
                }
                endPoint Solid {
                  translation -0.05 0 0.02
                  rotation 0 -1 0 4.171727373192664
                  children [
                    USE r5
                  ]
                  name "sr5"
                  boundingObject USE r5
                  physics Physics {
                    density -1
                    mass 0.1
                  }
                  linearVelocity 0.008552656580422062 -0.010347720369277575 -0.0798097640475587
                  angularVelocity 3.1900128102831706 -20.748807097657032 -0.6252025726825622
                }
              }
              DEF sr6 HingeJoint {
                jointParameters HingeJointParameters {
                  position 4942.825805268623
                  axis 0 1 0
                  anchor 0.05 0 0.02
                }
                endPoint Solid {
                  translation 0.05 0 0.02
                  rotation 0 1 0 4.2421538254683275
                  children [
                    USE r6
                  ]
                  name "sr6"
                  boundingObject USE r6
                  physics Physics {
                    density -1
                    mass 0.1
                  }
                  linearVelocity 0.006971951343424087 0.014352953370759066 -0.0589429391792985
                  angularVelocity -3.364471371132075 22.350140604568477 0.05886399097134981
                }
              }
              DEF sr7 HingeJoint {
                jointParameters HingeJointParameters {
                  position -1874.0215158241797
                  axis -0.707107 0.707107 0
                  anchor -0.03535 -0.03535 0.02
                }
                endPoint Solid {
                  translation -0.03535 -0.03535 0.02
                  rotation 0.7071067811865475 -0.7071067811865475 0 1.632294284662917
                  children [
                    USE r7
                  ]
                  name "sr7"
                  boundingObject USE r7
                  physics Physics {
                    density -1
                    mass 0.1
                  }
                  linearVelocity -0.0005919885787623999 -0.00801227825421375 -0.07807597799856025
                  angularVelocity 6.769738443615782 9.456685320319952 -0.933260573090756
                }
              }
              DEF sr8 HingeJoint {
                jointParameters HingeJointParameters {
                  position 3352.427022017931
                  axis -0.707107 0.707107 0
                  anchor 0.03535 0.03535 0.02
                }
                endPoint Solid {
                  translation 0.03535 0.03535 0.02
                  rotation 0.7071067811865476 -0.7071067811865476 0 2.7939320159681844
                  children [
                    USE r8
                  ]
                  name "sr8"
                  boundingObject USE r8
                  physics Physics {
                    density -1
                    mass 0.1
                  }
                  linearVelocity 0.01611659650266715 0.012017511261315204 -0.060676725228307714
                  angularVelocity -14.001342013593366 -18.944379944241202 1.070812917022652
                }
              }
              USE WHEEL_TRANS
            ]
            boundingObject Transform {
              translation 0 0 0.02
              rotation 1 0 0 1.5708
              children [
                DEF wheel1 Shape {
                  appearance PBRAppearance {
                    baseColor 0.8 0.8 0.8
                    transparency 0.12999999523162842
                    roughness 1
                    metalness 0
                    emissiveColor 0 1 0
                  }
                  geometry Cylinder {
                    height 0.02
                    radius 0.05
                  }
                }
              ]
            }
            physics Physics {
            }
            linearVelocity 0.007761972993606451 0.0020025651089589347 -0.06937685469684086
            angularVelocity 0.0056050239026540286 0.21306731725153838 -0.2513562146454151
          }
        }
      ]
      name "wheel 2"
      boundingObject USE DUMMY
      physics Physics {
      }
    }
    DEF SOLID3 Solid {
      rotation 0 1 0 4.18
      children [
        DEF WHEEL3 HingeJoint {
          jointParameters HingeJointParameters {
            position 168.29910855274588
            axis 0 0 1
            anchor 0 0 0.1
          }
          device [
            RotationalMotor {
              name "wheel3"
              maxVelocity 30.4
              maxTorque 0.847
            }
            PositionSensor {
              name "third_ps"
              resolution 0.00385
            }
          ]
          endPoint Solid {
            translation 0 0 0.15000000000000002
            rotation 0 0 1 4.940200006076083
            children [
              DEF sr1 HingeJoint {
                jointParameters HingeJointParameters {
                  position 291.3921316933022
                  anchor 0 0.05 0.02
                }
                endPoint Solid {
                  translation 0 0.05 0.02
                  rotation 0.9999999999999999 0 0 2.365607563041212
                  children [
                    USE r1
                  ]
                  name "sr1"
                  boundingObject USE r1
                  physics Physics {
                    density -1
                    mass 0.1
                  }
                  linearVelocity 0.07335930297029714 -0.0039007288695268047 -0.04902616753826587
                  angularVelocity 0.5669265607177252 -2.6944746313033283 0.7175072324482581
                }
              }
              DEF sr2 HingeJoint {
                jointParameters HingeJointParameters {
                  position 452.66669685782915
                  axis 0.707107 0.707107 0
                  anchor -0.03535 0.03535 0.02
                }
                endPoint Solid {
                  translation -0.03535 0.03535 0.02
                  rotation 0.7071067811865476 0.7071067811865476 0 0.27735474089892487
                  children [
                    USE r2
                  ]
                  name "sr2"
                  boundingObject USE r2
                  physics Physics {
                    density -1
                    mass 0.1
                  }
                  linearVelocity 0.06996920965249084 -0.0029872436005177064 -0.04512776967364736
                  angularVelocity 0.6998057118575804 -0.38714736068166966 0.9135960386790838
                }
              }
              DEF sr3 HingeJoint {
                jointParameters HingeJointParameters {
                  position 618.6349017954209
                  anchor 0 -0.05 0.02
                }
                endPoint Solid {
                  translation 0 -0.05 0.02
                  rotation 1 0 0 2.882741691821413
                  children [
                    USE r3
                  ]
                  name "sr3"
                  boundingObject USE r3
                  physics Physics {
                    density -1
                    mass 0.1
                  }
                  linearVelocity 0.0560249015122521 -0.00011709720894073519 -0.03797036995237297
                  angularVelocity 0.7209971241885119 -3.5309375595206567 0.931828917939011
                }
              }
              DEF sr4 HingeJoint {
                jointParameters HingeJointParameters {
                  position -438.1694655650136
                  axis 0.707107 0.707107 0
                  anchor 0.03535 -0.03535 0.02
                }
                endPoint Solid {
                  translation 0.03535 -0.03535 0.02
                  rotation 0.7071067811865476 0.7071067811865476 0 1.6535059375574719
                  children [
                    USE r4
                  ]
                  name "sr4"
                  boundingObject USE r4
                  physics Physics {
                    density -1
                    mass 0.1
                  }
                  linearVelocity 0.059301305141128566 -0.0010270752104797542 -0.0420320437616082
                  angularVelocity -3.4767228231136342 3.3581649147109482 -4.933992607650744
                }
              }
              DEF sr5 HingeJoint {
                jointParameters HingeJointParameters {
                  position 571.0375302039864
                  axis 0 1 0
                  anchor -0.05 0 0.02
                }
                endPoint Solid {
                  translation -0.05 0 0.02
                  rotation 0 1 0 5.550852557823638
                  children [
                    USE r5
                  ]
                  name "sr5"
                  boundingObject USE r5
                  physics Physics {
                    density -1
                    mass 0.1
                  }
                  linearVelocity 0.06348898554508456 -0.001500874523349224 -0.04027518031776097
                  angularVelocity -0.02149744479710112 0.18611802715698156 -0.09800404700640689
                }
              }
              DEF sr6 HingeJoint {
                jointParameters HingeJointParameters {
                  position -1618.393185518937
                  axis 0 1 0
                  anchor 0.05 0 0.02
                }
                endPoint Solid {
                  translation 0.05 0 0.02
                  rotation 0 1 0 2.668623733396422
                  children [
                    USE r6
                  ]
                  name "sr6"
                  boundingObject USE r6
                  physics Physics {
                    density -1
                    mass 0.1
                  }
                  linearVelocity 0.0660077236605786 -0.0025075566338918 -0.04656273491454465
                  angularVelocity -4.3561322949034 -2.1670167902482262 -6.20352786103231
                }
              }
              DEF sr7 HingeJoint {
                jointParameters HingeJointParameters {
                  position 33.95494495741311
                  axis -0.707107 0.707107 0
                  anchor -0.03535 -0.03535 0.02
                }
                endPoint Solid {
                  translation -0.03535 -0.03535 0.02
                  rotation 0.7071067811865476 -0.7071067811865476 0 3.744166885664407
                  children [
                    USE r7
                  ]
                  name "sr7"
                  boundingObject USE r7
                  physics Physics {
                    density -1
                    mass 0.1
                  }
                  linearVelocity 0.057713787821644685 -0.00031221601647927534 -0.03731132078041735
                  angularVelocity 0.0574316297198508 0.3137658366823354 0.013706960843128183
                }
              }
              DEF sr8 HingeJoint {
                jointParameters HingeJointParameters {
                  position -187.07229362128493
                  axis -0.707107 0.707107 0
                  anchor 0.03535 0.03535 0.02
                }
                endPoint Solid {
                  translation 0.03535 0.03535 0.02
                  rotation -0.7071067811865476 0.7071067811865476 0 1.4232655941026664
                  children [
                    USE r8
                  ]
                  name "sr8"
                  boundingObject USE r8
                  physics Physics {
                    density -1
                    mass 0.1
                  }
                  linearVelocity 0.07167041639289437 -0.0037056103263019653 -0.04968521709084218
                  angularVelocity -0.08514209600686312 -0.16528791614896488 -0.1895558223680611
                }
              }
              USE WHEEL_TRANS
            ]
            boundingObject Transform {
              translation 0 0 0.02
              rotation 1 0 0 1.5708
              children [
                DEF wheel1 Shape {
                  appearance PBRAppearance {
                    baseColor 0.8 0.8 0.8
                    transparency 0.12999999523162842
                    roughness 1
                    metalness 0
                    emissiveColor 0 1 0
                  }
                  geometry Cylinder {
                    height 0.02
                    radius 0.05
                  }
                }
              ]
            }
            physics Physics {
            }
            linearVelocity 0.06469234038086424 -0.0020089029334006215 -0.04349851695927565
            angularVelocity 0.027887235505850875 0.21289290168459693 -0.028457637193897715
          }
        }
      ]
      name "wheel 3"
      boundingObject USE DUMMY
      physics Physics {
      }
    }
    DEF BODY_TRANS Transform {
      translation 0 -0.05 0
      scale 4 4 4
      children [
        Shape {
          appearance Appearance {
            material Material {
              ambientIntensity 1
              diffuseColor 0.792157 0.819608 0.933333
              shininess 0.4
              specularColor 0.396078 0.409804 0.466667
            }
            texture ImageTexture {
              url [
                "/home/jesus/Documents/Computational_Modeling/u3_real_exam_Duarte_Jesus/protos/anaranjado.png"
              ]
            }
          }
          geometry IndexedFaceSet {
            coord Coordinate {
              point [
                -0.043284 0.04 -0.009731, -0.043284 0.045 -0.009731, -0.043211 0.04 -0.013447, -0.043211 0.045 -0.013447, -0.04276 0.04 -0.006052, -0.04276 0.045 -0.006052, -0.042542 0.04 -0.017103, -0.042542 0.045 -0.017103, -0.041653 0.04 -0.002504, -0.041653 0.045 -0.002504, -0.041297 0.04 -0.010023, -0.041297 0.045 -0.010023, -0.041296 0.04 -0.020604, -0.041296 0.045 -0.020604, -0.041208 0.04 -0.013368, -0.041208 0.045 -0.013368, -0.040857 0.04 -0.006705, -0.040857 0.045 -0.006705, -0.040591 0.04 -0.016656, -0.040591 0.045 -0.016656, -0.039992 0 0.000821, -0.039992 0.04 0.000821, -0.039992 0.045 0.000821, -0.039897 0.04 -0.0035, -0.039897 0.045 -0.0035, -0.039504 0.04 -0.02386, -0.039504 0.045 -0.02386, -0.039462 0.04 -0.019806, -0.039462 0.045 -0.019806, -0.037848 0.04 -0.022738, -0.037848 0.045 -0.022738, -0.037213 0.04 -0.026787, -0.037213 0.045 -0.026787, -0.035792 0.04 -0.025378, -0.035792 0.045 -0.025378, -0.034482 0.04 -0.029308, -0.034482 0.045 -0.029308, -0.033344 0.04 -0.027659, -0.033344 0.045 -0.027659, -0.031382 0.04 -0.031358, -0.031382 0.045 -0.031358, -0.030566 0.04 -0.029524, -0.030566 0.045 -0.029524, -0.027994 0.04 -0.032885, -0.027994 0.045 -0.032885, -0.027527 0.04 -0.030927, -0.027527 0.045 -0.030927, -0.024404 0.04 -0.033848, -0.024404 0.045 -0.033848, -0.024306 0.04 -0.031831, -0.024306 0.045 -0.031831, -0.020707 0 -0.034223, -0.020707 0.04 -0.034223, -0.020707 0.045 -0.034223, -0.019285 0 0.035044, -0.019285 0.04 0.035044, -0.019285 0.045 0.035044, -0.017111 0.04 0.038059, -0.017111 0.045 0.038059, -0.014482 0.04 0.040686, -0.014482 0.045 0.040686, -0.013087 0.04 0.037918, -0.013087 0.045 0.037918, -0.011466 0.04 0.042857, -0.011466 0.045 0.042857, -0.010396 0.04 0.039989, -0.010396 0.045 0.039989, -0.00814 0.04 0.044516, -0.00814 0.045 0.044516, -0.007396 0.04 0.041578, -0.007396 0.045 0.041578, -0.004592 0.04 0.045621, -0.004592 0.045 0.045621, -0.004171 0.04 0.042639, -0.004171 0.045 0.042639, -0.000912 0.04 0.046142, -0.000912 0.045 0.046142, -0.000813 0.04 0.043142, -0.000813 0.045 0.043142, 0.002582 0.04 0.043072, 0.002582 0.045 0.043072, 0.002804 0.04 0.046065, 0.002804 0.045 0.046065, 0.005916 0.04 0.042432, 0.005916 0.045 0.042432, 0.00646 0.04 0.045394, 0.00646 0.045 0.045394, 0.009096 0.04 0.04124, 0.009096 0.045 0.04124, 0.00996 0.04 0.044145, 0.00996 0.045 0.044145, 0.012028 0.04 0.039529, 0.012028 0.045 0.039529, 0.013215 0.04 0.042351, 0.013215 0.045 0.042351, 0.014631 0.04 0.037349, 0.014631 0.045 0.037349, 0.016139 0.04 0.040057, 0.016139 0.045 0.040057, 0.018659 0.04 0.037325, 0.018659 0.045 0.037325, 0.019285 0 -0.035044, 0.019285 0.04 -0.035044, 0.019285 0.045 -0.035044, 0.020707 0 0.034223, 0.020707 0.04 0.034223, 0.020707 0.045 0.034223, 0.022979 0.04 -0.032802, 0.022979 0.045 -0.032802, 0.022995 0.04 -0.034821, 0.022995 0.045 -0.034821, 0.026235 0.04 -0.03203, 0.026235 0.045 -0.03203, 0.026621 0.04 -0.034006, 0.026621 0.045 -0.034006, 0.029328 0.04 -0.030753, 0.029328 0.045 -0.030753, 0.030069 0.04 -0.03262, 0.030069 0.045 -0.03262, 0.032181 0.04 -0.029004, 0.032181 0.045 -0.029004, 0.033251 0.04 -0.030698, 0.033251 0.045 -0.030698, 0.03472 0.04 -0.026825, 0.03472 0.045 -0.026825, 0.036083 0.04 -0.028291, 0.036083 0.045 -0.028291, 0.036884 0.04 -0.024272, 0.036884 0.045 -0.024272, 0.038492 0.04 -0.025461, 0.038492 0.045 -0.025461, 0.038616 0.04 -0.021409, 0.038616 0.045 -0.021409, 0.03972 0.04 -0.005134, 0.03972 0.045 -0.005134, 0.039874 0.04 -0.018308, 0.039874 0.045 -0.018308, 0.039992 0 -0.000821, 0.039992 0.04 -0.000821, 0.039992 0.045 -0.000821, 0.040416 0.04 -0.022281, 0.040416 0.045 -0.022281, 0.040547 0.04 -0.008376, 0.040547 0.045 -0.008376, 0.040625 0.04 -0.015047, 0.040625 0.045 -0.015047, 0.040851 0.04 -0.011708, 0.040851 0.045 -0.011708, 0.041516 0.04 -0.00421, 0.041516 0.045 -0.00421, 0.041805 0.04 -0.018834, 0.041805 0.045 -0.018834, 0.042476 0.04 -0.007801, 0.042476 0.045 -0.007801, 0.042623 0.04 -0.015208, 0.042623 0.045 -0.015208, 0.042848 0.04 -0.011499, 0.042848 0.045 -0.011499
              ]
            }
            coordIndex [
              53, 103, 52, -1, 52, 103, 102, -1, 52, 102, 51, -1, 51, 102, 101, -1, 21, 52, 20, -1, 20, 52, 51, -1, 20, 54, 21, -1, 21, 54, 55, -1, 21, 55, 22, -1, 22, 55, 56, -1, 105, 55, 104, -1, 104, 55, 54, -1, 104, 137, 105, -1, 105, 137, 138, -1, 105, 138, 106, -1, 106, 138, 139, -1, 102, 138, 101, -1, 101, 138, 137, -1, 137, 104, 101, -1, 101, 104, 54, -1, 101, 54, 51, -1, 51, 54, 20, -1, 45, 47, 49, -1, 49, 47, 52, -1, 49, 52, 23, -1, 52, 21, 23, -1, 23, 21, 8, -1, 23, 8, 16, -1, 16, 8, 4, -1, 16, 4, 10, -1, 10, 4, 0, -1, 10, 0, 14, -1, 14, 0, 2, -1, 14, 2, 18, -1, 18, 2, 6, -1, 18, 6, 27, -1, 27, 6, 12, -1, 27, 12, 29, -1, 29, 12, 25, -1, 29, 25, 33, -1, 33, 25, 31, -1, 33, 31, 37, -1, 37, 31, 35, -1, 37, 35, 41, -1, 41, 35, 39, -1, 41, 39, 45, -1, 45, 39, 43, -1, 45, 43, 47, -1, 105, 95, 55, -1, 55, 95, 61, -1, 55, 61, 57, -1, 105, 99, 95, -1, 95, 99, 97, -1, 95, 97, 91, -1, 91, 97, 93, -1, 91, 93, 87, -1, 87, 93, 89, -1, 87, 89, 83, -1, 83, 89, 85, -1, 83, 85, 79, -1, 79, 85, 81, -1, 79, 81, 77, -1, 77, 81, 75, -1, 77, 75, 73, -1, 73, 75, 71, -1, 73, 71, 69, -1, 69, 71, 67, -1, 69, 67, 65, -1, 65, 67, 63, -1, 65, 63, 61, -1, 61, 63, 59, -1, 61, 59, 57, -1, 53, 52, 47, -1, 53, 47, 48, -1, 48, 47, 43, -1, 48, 43, 44, -1, 44, 43, 39, -1, 44, 39, 40, -1, 40, 39, 35, -1, 40, 35, 36, -1, 36, 35, 31, -1, 36, 31, 32, -1, 32, 31, 25, -1, 32, 25, 26, -1, 26, 25, 12, -1, 26, 12, 13, -1, 13, 12, 6, -1, 13, 6, 7, -1, 7, 6, 2, -1, 7, 2, 3, -1, 3, 2, 0, -1, 3, 0, 1, -1, 1, 0, 4, -1, 1, 4, 5, -1, 5, 4, 8, -1, 5, 8, 9, -1, 9, 8, 21, -1, 9, 21, 22, -1, 56, 55, 57, -1, 56, 57, 58, -1, 58, 57, 59, -1, 58, 59, 60, -1, 60, 59, 63, -1, 60, 63, 64, -1, 64, 63, 67, -1, 64, 67, 68, -1, 68, 67, 71, -1, 68, 71, 72, -1, 72, 71, 75, -1, 72, 75, 76, -1, 76, 75, 81, -1, 76, 81, 82, -1, 82, 81, 85, -1, 82, 85, 86, -1, 86, 85, 89, -1, 86, 89, 90, -1, 90, 89, 93, -1, 90, 93, 94, -1, 94, 93, 97, -1, 94, 97, 98, -1, 98, 97, 99, -1, 98, 99, 100, -1, 100, 99, 105, -1, 100, 105, 106, -1, 139, 138, 148, -1, 139, 148, 149, -1, 149, 148, 152, -1, 149, 152, 153, -1, 153, 152, 156, -1, 153, 156, 157, -1, 157, 156, 154, -1, 157, 154, 155, -1, 155, 154, 150, -1, 155, 150, 151, -1, 151, 150, 140, -1, 151, 140, 141, -1, 141, 140, 129, -1, 141, 129, 130, -1, 130, 129, 125, -1, 130, 125, 126, -1, 126, 125, 121, -1, 126, 121, 122, -1, 122, 121, 117, -1, 122, 117, 118, -1, 118, 117, 113, -1, 118, 113, 114, -1, 114, 113, 109, -1, 114, 109, 110, -1, 110, 109, 102, -1, 110, 102, 103, -1, 9, 24, 17, -1, 62, 50, 24, -1, 103, 108, 110, -1, 110, 108, 112, -1, 62, 60, 66, -1, 66, 60, 64, -1, 66, 64, 70, -1, 70, 64, 68, -1, 70, 68, 74, -1, 74, 68, 72, -1, 74, 72, 78, -1, 78, 72, 76, -1, 78, 76, 80, -1, 80, 76, 82, -1, 80, 82, 84, -1, 84, 82, 86, -1, 84, 86, 88, -1, 88, 86, 90, -1, 88, 90, 92, -1, 92, 90, 94, -1, 92, 94, 96, -1, 96, 94, 98, -1, 96, 98, 100, -1, 9, 22, 24, -1, 24, 22, 56, -1, 24, 56, 62, -1, 62, 56, 58, -1, 62, 58, 60, -1, 134, 108, 96, -1, 96, 108, 103, -1, 96, 103, 62, -1, 62, 103, 53, -1, 62, 53, 50, -1, 50, 53, 48, -1, 50, 48, 46, -1, 46, 48, 44, -1, 46, 44, 42, -1, 42, 44, 40, -1, 42, 40, 38, -1, 38, 40, 36, -1, 38, 36, 34, -1, 34, 36, 32, -1, 34, 32, 30, -1, 30, 32, 26, -1, 30, 26, 28, -1, 28, 26, 13, -1, 28, 13, 19, -1, 19, 13, 7, -1, 19, 7, 15, -1, 15, 7, 3, -1, 15, 3, 11, -1, 11, 3, 1, -1, 11, 1, 17, -1, 17, 1, 5, -1, 17, 5, 9, -1, 100, 106, 96, -1, 96, 106, 139, -1, 96, 139, 134, -1, 134, 139, 149, -1, 134, 149, 143, -1, 143, 149, 153, -1, 143, 153, 147, -1, 147, 153, 157, -1, 147, 157, 145, -1, 145, 157, 155, -1, 145, 155, 136, -1, 136, 155, 151, -1, 136, 151, 132, -1, 132, 151, 141, -1, 132, 141, 128, -1, 128, 141, 130, -1, 128, 130, 124, -1, 124, 130, 126, -1, 124, 126, 120, -1, 120, 126, 122, -1, 120, 122, 116, -1, 116, 122, 118, -1, 116, 118, 112, -1, 112, 118, 114, -1, 112, 114, 110, -1, 142, 148, 133, -1, 133, 148, 138, -1, 133, 138, 107, -1, 138, 102, 107, -1, 107, 102, 109, -1, 107, 109, 111, -1, 111, 109, 113, -1, 111, 113, 115, -1, 115, 113, 117, -1, 115, 117, 119, -1, 119, 117, 121, -1, 119, 121, 123, -1, 123, 121, 125, -1, 123, 125, 127, -1, 127, 125, 129, -1, 127, 129, 131, -1, 131, 129, 140, -1, 131, 140, 135, -1, 135, 140, 150, -1, 135, 150, 144, -1, 144, 150, 154, -1, 144, 154, 146, -1, 146, 154, 156, -1, 146, 156, 142, -1, 142, 156, 152, -1, 142, 152, 148, -1, 96, 95, 92, -1, 92, 95, 91, -1, 92, 91, 88, -1, 88, 91, 87, -1, 88, 87, 84, -1, 84, 87, 83, -1, 84, 83, 80, -1, 80, 83, 79, -1, 80, 79, 78, -1, 78, 79, 77, -1, 78, 77, 74, -1, 74, 77, 73, -1, 74, 73, 70, -1, 70, 73, 69, -1, 70, 69, 66, -1, 66, 69, 65, -1, 66, 65, 62, -1, 62, 65, 61, -1, 61, 95, 62, -1, 62, 95, 96, -1, 108, 107, 112, -1, 112, 107, 111, -1, 112, 111, 116, -1, 116, 111, 115, -1, 116, 115, 120, -1, 120, 115, 119, -1, 120, 119, 124, -1, 124, 119, 123, -1, 124, 123, 128, -1, 128, 123, 127, -1, 128, 127, 132, -1, 132, 127, 131, -1, 132, 131, 136, -1, 136, 131, 135, -1, 136, 135, 145, -1, 145, 135, 144, -1, 145, 144, 147, -1, 147, 144, 146, -1, 147, 146, 143, -1, 143, 146, 142, -1, 143, 142, 134, -1, 134, 142, 133, -1, 133, 107, 134, -1, 134, 107, 108, -1, 24, 23, 17, -1, 17, 23, 16, -1, 17, 16, 11, -1, 11, 16, 10, -1, 11, 10, 15, -1, 15, 10, 14, -1, 15, 14, 19, -1, 19, 14, 18, -1, 19, 18, 28, -1, 28, 18, 27, -1, 28, 27, 30, -1, 30, 27, 29, -1, 30, 29, 34, -1, 34, 29, 33, -1, 34, 33, 38, -1, 38, 33, 37, -1, 38, 37, 42, -1, 42, 37, 41, -1, 42, 41, 46, -1, 46, 41, 45, -1, 46, 45, 50, -1, 50, 45, 49, -1, 49, 23, 50, -1, 50, 23, 24, -1
            ]
          }
        }
      ]
    }
    DEF left DistanceSensor {
      translation 0.15 0.04 0
      name "left_light"
      lookupTable [
        0 0 0
        0.2 65535 0
      ]
    }
    DEF right DistanceSensor {
      translation 0.1 0.04 0.1
      rotation 0 1 0 -0.9162996938995747
      name "right_light"
      lookupTable [
        0 0 0
        0.2 65535 0
      ]
    }
    DEF Post Transform {
      translation 0 0.21 0
      children [
        Transform {
          children [
            Shape {
              appearance PBRAppearance {
                baseColor 0.8 0 0
                roughness 1
              }
              geometry Cylinder {
                height 0.2
                radius 0.03
              }
            }
            DEF Gun HingeJoint {
              jointParameters HingeJointParameters {
                position 239.99280019784146
                axis 0 1 0
              }
              device [
                RotationalMotor {
                  name "motor_4"
                }
              ]
              endPoint Solid {
                rotation 0 1 0 1.2317585250171752
                children [
                  DEF Gun Transform {
                    translation 0.05 0.05 0
                    rotation 0 0 1 1.5708
                    children [
                      Shape {
                        appearance PBRAppearance {
                          baseColor 0 0 0
                        }
                        geometry DEF sensor Cylinder {
                          height 0.05
                          radius 0.02
                        }
                      }
                    ]
                  }
                  DistanceSensor {
                    name "se"
                  }
                ]
                name "1"
                boundingObject USE Gun
                physics Physics {
                }
                linearVelocity 0.04385006329177755 -0.0011918988847544197 -0.05778054980566103
                angularVelocity 0.02797838899895479 0.2128204037463437 -0.02833817588529819
              }
            }
            DEF Radar HingeJoint {
              jointParameters HingeJointParameters {
                position 25.755983724946233
                axis 0 1 0
              }
              device [
                RotationalMotor {
                  name "motor_5"
                }
              ]
              endPoint Solid {
                rotation 0 1 0 0.6232424962278874
                children [
                  DEF Radar Transform {
                    translation 0.05 0 0
                    rotation 0 0 1 1.5708
                    children [
                      Shape {
                        appearance PBRAppearance {
                          baseColor 0.9294117647058824 0.8313725490196079 0
                        }
                        geometry USE sensor
                      }
                    ]
                  }
                ]
                name "other"
                boundingObject USE Radar
                physics Physics {
                }
                linearVelocity 0.03932523698602731 -0.0015297695064386385 -0.06478565883031992
                angularVelocity 0.02797837987799149 0.2128193942391416 -0.02833818183904394
              }
            }
          ]
        }
      ]
    }
  ]
  name "robot(1)"
  boundingObject USE BODY_TRANS
  physics Physics {
  }
  controller "u3_real_exam"
  linearVelocity 0.044938139646050264 -0.0032022968062100894 -0.07183408752062209
  angularVelocity 0.027978375927142626 0.21281988461633752 -0.02833818094760122
}
DEF wall Solid {
  translation 3.2499999999999996 0.6 -2.3600000000000003
  rotation 0 1 0 6.021385901
  children [
    DEF wall Shape {
      appearance PBRAppearance {
      }
      geometry Box {
        size 2.9 1.2000000000000002 0.30000000000000004
      }
    }
  ]
  name "solid(1)"
  boundingObject USE wall
}
DEF wall Solid {
  translation 0.19738897345219494 0.6000000811296518 -1.8631439639103151
  rotation -0.2588190443306021 7.1923452487111625e-09 -0.9659258264959034 3.141592678504807
  children [
    DEF wall Shape {
      appearance PBRAppearance {
      }
      geometry Box {
        size 2.9 1.2000000000000002 0.30000000000000004
      }
    }
  ]
  name "solid(3)"
  boundingObject USE wall
}
DEF wall Solid {
  translation 2.147430792230632 0.6 1.754843999725728
  rotation -6.787767695857421e-08 0.9999999999999972 -2.81158549076604e-08 0.2617993678204156
  children [
    DEF wall Shape {
      appearance PBRAppearance {
      }
      geometry Box {
        size 2.9 1.2000000000000002 0.30000000000000004
      }
    }
  ]
  name "solid(2)"
  boundingObject USE wall
}
DEF wall Solid {
  translation 4.214887571329155 0.599999954113144 -0.16806433571955157
  rotation -1.356201641076181e-08 0.9999999999999999 -1.3562016558692992e-08 1.0471975288204154
  children [
    DEF wall Shape {
      appearance PBRAppearance {
      }
      geometry Box {
        size 2.9 1.2000000000000002 0.30000000000000004
      }
    }
  ]
  name "solid(6)"
  boundingObject USE wall
}
DEF wall Solid {
  translation -1.2719466511375728 0.600000033947869 2.6710633510738164
  rotation -6.787767695857421e-08 0.9999999999999972 -2.81158549076604e-08 0.2617993678204156
  children [
    DEF wall Shape {
      appearance PBRAppearance {
      }
      geometry Box {
        size 2.9 1.2000000000000002 0.30000000000000004
      }
    }
  ]
  name "solid(4)"
  boundingObject USE wall
}
DEF wall Solid {
  translation -3.181674765827451 0.6000000054288959 0.6199554568717361
  rotation -9.589793718731934e-09 0.9999999999999999 -1.2497662625355229e-08 1.3089969158204156
  children [
    DEF wall Shape {
      appearance PBRAppearance {
      }
      geometry Box {
        size 2.9 1.2000000000000002 0.30000000000000004
      }
    }
  ]
  name "solid(5)"
  boundingObject USE wall
}
