#VRML_SIM R2019a utf8
WorldInfo {
}
Viewpoint {
  orientation -0.2636489322986337 -0.8993142571178306 -0.3488883882309569 1.9216665869232405
  position -1.3421323076426697 1.5478402619799496 -0.2558516683785802
}
TexturedBackground {
}
TexturedBackgroundLight {
}
Floor {
}
DEF THREE_WHEELS Robot {
  translation 0.22451011516819705 0.059549739493783074 -0.14540624948249944
  rotation -0.0032711161587670855 -0.9996227806120099 -0.027268961853899792 -1.1261762269597284
  children [
    DEF SOLID1 Solid {
      children [
        DEF WHEEL1 HingeJoint {
          jointParameters HingeJointParameters {
            position -430.48334536422124
            axis 0 0 1
            anchor 0 0 0.1
          }
          device [
            RotationalMotor {
              name "wheel1"
              maxVelocity 30.4
              maxTorque 0.847
            }
            PositionSensor {
              name "first_ps"
              resolution 0.00385
            }
          ]
          endPoint Solid {
            translation 0 0 0.15000000000000002
            rotation 0 0 -0.9999999999999999 3.2267444760093555
            children [
              DEF sr1 HingeJoint {
                jointParameters HingeJointParameters {
                  position -5050.718165881527
                  anchor 0 0.05 0.02
                }
                endPoint Solid {
                  translation 0 0.05 0.02
                  rotation 0.9999999999999999 0 0 0.9628210908604709
                  children [
                    DEF r1 Transform {
                      rotation 0 0 1 1.5708
                      children [
                        DEF SMALL_WHEEL_SHAPE Shape {
                          appearance PBRAppearance {
                            baseColor 0 0 0
                            roughness 1
                            metalness 0
                          }
                          geometry Cylinder {
                            height 0.02
                            radius 0.01
                          }
                        }
                      ]
                    }
                  ]
                  name "sr1"
                  boundingObject USE r1
                  physics Physics {
                    density -1
                    mass 0.1
                  }
                  linearVelocity 0.25041098010514695 -0.06691869367100459 0.023130584962874227
                  angularVelocity 2.7513008725995376 3.5742213114694428 -23.204383227808563
                }
              }
              DEF sr2 HingeJoint {
                jointParameters HingeJointParameters {
                  position -2410.3973827627055
                  axis 0.707107 0.707107 0
                  anchor -0.03535 0.03535 0.02
                }
                endPoint Solid {
                  translation -0.03535 0.03535 0.02
                  rotation 0.7071067811865475 0.7071067811865475 0 2.34577519425566
                  children [
                    DEF r2 Transform {
                      rotation 0 0 1 2.27
                      children [
                        USE SMALL_WHEEL_SHAPE
                      ]
                    }
                  ]
                  name "sr2"
                  boundingObject USE r2
                  physics Physics {
                    density -1
                    mass 0.1
                  }
                  linearVelocity 0.31132204741484143 -0.31824161514857124 -0.10719530038122449
                  angularVelocity -6.649486484945193 -0.10751714018867092 -3.0604228140942555
                }
              }
              DEF sr3 HingeJoint {
                jointParameters HingeJointParameters {
                  position 3273.514065940534
                  anchor 0 -0.05 0.02
                }
                endPoint Solid {
                  translation 0 -0.05 0.02
                  rotation 1 0 0 6.257706207148807
                  children [
                    DEF r3 Transform {
                      rotation 0 0 1 1.5708
                      children [
                        USE SMALL_WHEEL_SHAPE
                      ]
                    }
                  ]
                  name "sr3"
                  boundingObject USE r3
                  physics Physics {
                    density -1
                    mass 0.1
                  }
                  linearVelocity 0.5753895101649783 0.02926650922590232 -0.6529328528422824
                  angularVelocity -11.951062618490734 -1.7202354998783038 6.879447189692138
                }
              }
              DEF sr4 HingeJoint {
                jointParameters HingeJointParameters {
                  position 4613.476028626304
                  axis 0.707107 0.707107 0
                  anchor 0.03535 -0.03535 0.02
                }
                endPoint Solid {
                  translation 0.03535 -0.03535 0.02
                  rotation 0.7071067811865476 0.7071067811865476 0 1.6180131564870854
                  children [
                    DEF r4 Transform {
                      rotation 0 0 1 2.27
                      children [
                        USE SMALL_WHEEL_SHAPE
                      ]
                    }
                  ]
                  name "sr4"
                  boundingObject USE r4
                  physics Physics {
                    density -1
                    mass 0.1
                  }
                  linearVelocity 0.5144344487593372 0.2803798223578099 -0.5224766472126595
                  angularVelocity -9.907532101031663 -9.344325765733908 2.8670878520121215
                }
              }
              DEF sr5 HingeJoint {
                jointParameters HingeJointParameters {
                  position -5592.277424345793
                  axis 0 1 0
                  anchor -0.05 0 0.02
                }
                endPoint Solid {
                  translation -0.05 0 0.02
                  rotation 0 -1 0 0.24250095596144103
                  children [
                    DEF r5 Transform {
                      children [
                        USE SMALL_WHEEL_SHAPE
                      ]
                    }
                  ]
                  name "sr5"
                  boundingObject USE r5
                  physics Physics {
                    density -1
                    mass 0.1
                  }
                  linearVelocity 0.43174482868463177 -0.3941009023928651 -0.3592396897979647
                  angularVelocity -6.589265438629481 -0.09091989828119582 -3.1861807190149594
                }
              }
              DEF sr6 HingeJoint {
                jointParameters HingeJointParameters {
                  position 6748.073978813104
                  axis 0 1 0
                  anchor 0.05 0 0.02
                }
                endPoint Solid {
                  translation 0.05 0 0.02
                  rotation 0 -1 0 0.06704109777179675
                  children [
                    DEF r6 Transform {
                      children [
                        USE SMALL_WHEEL_SHAPE
                      ]
                    }
                  ]
                  name "sr6"
                  boundingObject USE r6
                  physics Physics {
                    density -1
                    mass 0.1
                  }
                  linearVelocity 0.3940024524743254 0.3561441747135943 -0.2704152682718586
                  angularVelocity -5.495973034608462 -18.72299660301278 -6.15134299461663
                }
              }
              DEF sr7 HingeJoint {
                jointParameters HingeJointParameters {
                  position -2990.4521061937958
                  axis -0.707107 0.707107 0
                  anchor -0.03535 -0.03535 0.02
                }
                endPoint Solid {
                  translation -0.03535 -0.03535 0.02
                  rotation -0.7071067811865475 0.7071067811865475 0 0.3441000236873925
                  children [
                    DEF r7 Transform {
                      rotation 0 0 1 0.76
                      children [
                        USE SMALL_WHEEL_SHAPE
                      ]
                    }
                  ]
                  name "sr7"
                  boundingObject USE r7
                  physics Physics {
                    density -1
                    mass 0.1
                  }
                  linearVelocity 0.5411121389561849 -0.25010468195558583 -0.5852637318505108
                  angularVelocity -6.49809466121758 -0.1373645113271834 -3.3750192272239086
                }
              }
              DEF sr8 HingeJoint {
                jointParameters HingeJointParameters {
                  position 5886.795648480107
                  axis -0.707107 0.707107 0
                  anchor 0.03535 0.03535 0.02
                }
                endPoint Solid {
                  translation 0.03535 0.03535 0.02
                  rotation -0.7071067811865475 0.7071067811865475 0 5.734200960014105
                  children [
                    DEF r8 Transform {
                      rotation 0 0 1 0.76
                      children [
                        USE SMALL_WHEEL_SHAPE
                      ]
                    }
                  ]
                  name "sr8"
                  boundingObject USE r8
                  physics Physics {
                    density -1
                    mass 0.1
                  }
                  linearVelocity 0.28462732943503777 0.21205477543034748 -0.04438433643866687
                  angularVelocity 4.776853193056672 -18.760272961659112 -27.898944441979403
                }
              }
              DEF WHEEL_TRANS Transform {
                translation 0 0 0.02
                rotation 1 0 0 1.5708
                children [
                  DEF WHEEL_SHAPE Shape {
                    appearance PBRAppearance {
                      baseColor 0.5333333333333333 0.5411764705882353 0.5215686274509804
                      roughness 1
                      metalness 0
                    }
                    geometry Cylinder {
                      height 0.02
                      radius 0.05
                      subdivision 20
                    }
                  }
                ]
              }
            ]
            boundingObject Transform {
              translation 0 0 0.02
              rotation 1 0 0 1.5708
              children [
                DEF wheel1 Shape {
                  appearance PBRAppearance {
                    baseColor 0.8 0.8 0.8
                    transparency 0.12999999523162842
                    roughness 1
                    metalness 0
                    emissiveColor 0 1 0
                  }
                  geometry Cylinder {
                    height 0.02
                    radius 0.05
                  }
                }
              ]
            }
            physics Physics {
            }
            linearVelocity 0.4128779048474999 -0.018925277797154638 -0.3148370598724946
            angularVelocity -6.604003899561148 0.0550485554440982 -3.1596345814262996
          }
        }
      ]
      name "wheel 1"
      boundingObject DEF DUMMY Sphere {
        radius 0.01
      }
      physics Physics {
      }
    }
    DEF SOLID2 Solid {
      rotation 0 1 0 2.09
      children [
        DEF WHEEL2 HingeJoint {
          jointParameters HingeJointParameters {
            position 355.06254172629696
            axis 0 0 1
            anchor 0 0 0.1
          }
          device [
            RotationalMotor {
              name "wheel2"
              maxVelocity 30.4
              maxTorque 0.847
            }
            PositionSensor {
              name "second_ps"
              resolution 0.00385
            }
          ]
          endPoint Solid {
            translation 0 0 0.14999999999999997
            rotation 0 0 1 3.2065703342397036
            children [
              DEF sr1 HingeJoint {
                jointParameters HingeJointParameters {
                  position -5456.526636048037
                  anchor 0 0.05 0.02
                }
                endPoint Solid {
                  translation 0 0.05 0.02
                  rotation -1 0 0 2.7217894161562275
                  children [
                    USE r1
                  ]
                  name "sr1"
                  boundingObject USE r1
                  physics Physics {
                    density -1
                    mass 0.1
                  }
                  linearVelocity -0.03561311470533947 -0.13240577688034333 -0.25692285413328486
                  angularVelocity -25.799068963279407 -5.2712741032473165 -6.61015801767627
                }
              }
              DEF sr2 HingeJoint {
                jointParameters HingeJointParameters {
                  position -4010.3489663333157
                  axis 0.707107 0.707107 0
                  anchor -0.03535 0.03535 0.02
                }
                endPoint Solid {
                  translation -0.03535 0.03535 0.02
                  rotation -0.7071067811865476 -0.7071067811865476 0 1.6767403527395572
                  children [
                    USE r2
                  ]
                  name "sr2"
                  boundingObject USE r2
                  physics Physics {
                    density -1
                    mass 0.1
                  }
                  linearVelocity 0.031117360128421576 0.18302935667872244 -0.25022734434884164
                  angularVelocity -14.783040610351382 9.440973033510952 -7.663428710165887
                }
              }
              DEF sr3 HingeJoint {
                jointParameters HingeJointParameters {
                  position 2693.617473783624
                  anchor 0 -0.05 0.02
                }
                endPoint Solid {
                  translation 0 -0.05 0.02
                  rotation 1 0 0 4.414162310761052
                  children [
                    USE r3
                  ]
                  name "sr3"
                  boundingObject USE r3
                  physics Physics {
                    density -1
                    mass 0.1
                  }
                  linearVelocity 0.7897216388608194 0.02388373425936069 -0.3238243328597367
                  angularVelocity 13.61510909432801 3.527250023071816 -9.677353447019364
                }
              }
              DEF sr4 HingeJoint {
                jointParameters HingeJointParameters {
                  position 5969.574548452009
                  axis 0.707107 0.707107 0
                  anchor 0.03535 -0.03535 0.02
                }
                endPoint Solid {
                  translation 0.03535 -0.03535 0.02
                  rotation 0.7071067811865476 0.7071067811865476 0 0.5485066314022139
                  children [
                    USE r4
                  ]
                  name "sr4"
                  boundingObject USE r4
                  physics Physics {
                    density -1
                    mass 0.1
                  }
                  linearVelocity 0.7229172283780625 -0.2914954396909871 -0.33052200552144506
                  angularVelocity 4.392852075509045 -3.2435641725508297 -8.769037007748368
                }
              }
              DEF sr5 HingeJoint {
                jointParameters HingeJointParameters {
                  position -1977.9612274441806
                  axis 0 1 0
                  anchor -0.05 0 0.02
                }
                endPoint Solid {
                  translation -0.05 0 0.02
                  rotation 0 -1 0 5.041040989790468
                  children [
                    USE r5
                  ]
                  name "sr5"
                  boundingObject USE r5
                  physics Physics {
                    density -1
                    mass 0.1
                  }
                  linearVelocity 0.30047437864621196 0.35946190660203314 -0.26703045960431454
                  angularVelocity -4.922724675112927 18.133797855763355 -8.017394546761272
                }
              }
              DEF sr6 HingeJoint {
                jointParameters HingeJointParameters {
                  position 3794.7696356685456
                  axis 0 1 0
                  anchor 0.05 0 0.02
                }
                endPoint Solid {
                  translation 0.05 0 0.02
                  rotation 0 -1 0 0.27428986792467164
                  children [
                    USE r6
                  ]
                  name "sr6"
                  boundingObject USE r6
                  physics Physics {
                    density -1
                    mass 0.1
                  }
                  linearVelocity 0.45357758798314485 -0.467897132820657 -0.31370933370722026
                  angularVelocity 0.18160893335180095 -5.0397433158967875 -8.46837502179405
                }
              }
              DEF sr7 HingeJoint {
                jointParameters HingeJointParameters {
                  position -1668.7344536098835
                  axis -0.707107 0.707107 0
                  anchor -0.03535 -0.03535 0.02
                }
                endPoint Solid {
                  translation -0.03535 -0.03535 0.02
                  rotation -0.7071067811865476 0.7071067811865476 0 2.5928380998864724
                  children [
                    USE r7
                  ]
                  name "sr7"
                  boundingObject USE r7
                  physics Physics {
                    density -1
                    mass 0.1
                  }
                  linearVelocity 0.6146835915269867 0.29348669926752596 -0.29752055040935854
                  angularVelocity 5.1728712261680485 9.339556358019557 -8.776350487547527
                }
              }
              DEF sr8 HingeJoint {
                jointParameters HingeJointParameters {
                  position 2663.5250504515875
                  axis -0.707107 0.707107 0
                  anchor 0.03535 0.03535 0.02
                }
                endPoint Solid {
                  translation 0.03535 0.03535 0.02
                  rotation 0.7071067811865476 -0.7071067811865476 0 0.5455197925571625
                  children [
                    USE r8
                  ]
                  name "sr8"
                  boundingObject USE r8
                  physics Physics {
                    density -1
                    mass 0.1
                  }
                  linearVelocity 0.13938595360355224 -0.40184857292329856 -0.28322112110208175
                  angularVelocity -0.705663342628643 0.33790336515017805 -8.031811824395644
                }
              }
              USE WHEEL_TRANS
            ]
            boundingObject Transform {
              translation 0 0 0.02
              rotation 1 0 0 1.5708
              children [
                DEF wheel1 Shape {
                  appearance PBRAppearance {
                    baseColor 0.8 0.8 0.8
                    transparency 0.12999999523162842
                    roughness 1
                    metalness 0
                    emissiveColor 0 1 0
                  }
                  geometry Cylinder {
                    height 0.02
                    radius 0.05
                  }
                }
              ]
            }
            physics Physics {
            }
            linearVelocity 0.3770368953125339 -0.054167927258849446 -0.29037257017216955
            angularVelocity -0.7296790273903673 0.32404155651740363 -8.029578341096071
          }
        }
      ]
      name "wheel 2"
      boundingObject USE DUMMY
      physics Physics {
      }
    }
    DEF SOLID3 Solid {
      rotation 0 1 0 4.18
      children [
        DEF WHEEL3 HingeJoint {
          jointParameters HingeJointParameters {
            position 164.7222525720466
            axis 0 0 1
            anchor 0 0 0.1
          }
          device [
            RotationalMotor {
              name "wheel3"
              maxVelocity 30.4
              maxTorque 0.847
            }
            PositionSensor {
              name "third_ps"
              resolution 0.00385
            }
          ]
          endPoint Solid {
            translation 0 0 0.15000000000000002
            rotation 0 0 1 1.3633440253769318
            children [
              DEF sr1 HingeJoint {
                jointParameters HingeJointParameters {
                  position -164.38935445101868
                  anchor 0 0.05 0.02
                }
                endPoint Solid {
                  translation 0 0.05 0.02
                  rotation -0.9999999999999999 0 0 1.0265364643494275
                  children [
                    USE r1
                  ]
                  name "sr1"
                  boundingObject USE r1
                  physics Physics {
                    density -1
                    mass 0.1
                  }
                  linearVelocity 0.411500315170394 0.00768983238844232 -0.2658410556522618
                  angularVelocity 0.04115932469114414 0.03941330746094257 -0.22612803937659137
                }
              }
              DEF sr2 HingeJoint {
                jointParameters HingeJointParameters {
                  position 382.3550296716004
                  axis 0.707107 0.707107 0
                  anchor -0.03535 0.03535 0.02
                }
                endPoint Solid {
                  translation -0.03535 0.03535 0.02
                  rotation 0.7071067811865476 0.7071067811865476 0 5.363911240825202
                  children [
                    USE r2
                  ]
                  name "sr2"
                  boundingObject USE r2
                  physics Physics {
                    density -1
                    mass 0.1
                  }
                  linearVelocity 0.40465497009988965 0.006494729757822131 -0.26855103959324983
                  angularVelocity 0.11803160133687968 -0.016402745982650013 -0.11272499480259374
                }
              }
              DEF sr3 HingeJoint {
                jointParameters HingeJointParameters {
                  position 632.6937339969817
                  anchor 0 -0.05 0.02
                }
                endPoint Solid {
                  translation 0 -0.05 0.02
                  rotation 1 0 0 4.3752032790230295
                  children [
                    USE r3
                  ]
                  name "sr3"
                  boundingObject USE r3
                  physics Physics {
                    density -1
                    mass 0.1
                  }
                  linearVelocity 0.4198919671082195 -0.007546824184190066 -0.27553049893601983
                  angularVelocity 0.04115931743859441 0.039413230176113104 -0.22612805346536757
                }
              }
              DEF sr4 HingeJoint {
                jointParameters HingeJointParameters {
                  position -220.59014671267178
                  axis 0.707107 0.707107 0
                  anchor 0.03535 -0.03535 0.02
                }
                endPoint Solid {
                  translation 0.03535 -0.03535 0.02
                  rotation 0.7071067811865476 0.7071067811865476 0 5.604524345793331
                  children [
                    USE r4
                  ]
                  name "sr4"
                  boundingObject USE r4
                  physics Physics {
                    density -1
                    mass 0.1
                  }
                  linearVelocity 0.42673731217872557 -0.006351721553567374 -0.27282051499503596
                  angularVelocity 0.11793196059427252 -0.016154243143642444 -0.11284916028878744
                }
              }
              DEF sr5 HingeJoint {
                jointParameters HingeJointParameters {
                  position 412.1852871868476
                  axis 0 1 0
                  anchor -0.05 0 0.02
                }
                endPoint Solid {
                  translation -0.05 0 0.02
                  rotation 0 -0.9999999999999999 0 2.504943087005133
                  children [
                    USE r5
                  ]
                  name "sr5"
                  boundingObject USE r5
                  physics Physics {
                    density -1
                    mass 0.1
                  }
                  linearVelocity 0.40421704901874655 0.0015294395977722532 -0.2725965477751614
                  angularVelocity -26.580474310191555 10.038899551136996 -39.41615065194876
                }
              }
              DEF sr6 HingeJoint {
                jointParameters HingeJointParameters {
                  position -1566.9083748715636
                  axis 0 1 0
                  anchor 0.05 0 0.02
                }
                endPoint Solid {
                  translation 0.05 0 0.02
                  rotation 0 1 0 3.887951923332982
                  children [
                    USE r6
                  ]
                  name "sr6"
                  boundingObject USE r6
                  physics Physics {
                    density -1
                    mass 0.1
                  }
                  linearVelocity 0.42711724733364453 -0.0013953524145151525 -0.26886048662948303
                  angularVelocity 0.1434321374613357 0.12116264790186246 -0.0662739010377083
                }
              }
              DEF sr7 HingeJoint {
                jointParameters HingeJointParameters {
                  position -188.07474281320674
                  axis -0.707107 0.707107 0
                  anchor -0.03535 -0.03535 0.02
                }
                endPoint Solid {
                  translation -0.03535 -0.03535 0.02
                  rotation -0.7071067811865475 0.7071067811865475 0 0.42081640218085425
                  children [
                    USE r7
                  ]
                  name "sr7"
                  boundingObject USE r7
                  physics Physics {
                    density -1
                    mass 0.1
                  }
                  linearVelocity 0.410581819634299 -0.004240507035755703 -0.2754116846002276
                  angularVelocity -21.04746675586001 -25.56098462834317 -33.405523260326525
                }
              }
              DEF sr8 HingeJoint {
                jointParameters HingeJointParameters {
                  position 168.1440277553275
                  axis -0.707107 0.707107 0
                  anchor 0.03535 0.03535 0.02
                }
                endPoint Solid {
                  translation 0.03535 0.03535 0.02
                  rotation -0.7071067811865476 0.7071067811865476 0 4.781209768658251
                  children [
                    USE r8
                  ]
                  name "sr8"
                  boundingObject USE r8
                  physics Physics {
                    density -1
                    mass 0.1
                  }
                  linearVelocity 0.420804414258676 0.004420594643291123 -0.26597007859342214
                  angularVelocity 0.06762223098843528 0.17551772299147178 -0.17816513846394394
                }
              }
              USE WHEEL_TRANS
            ]
            boundingObject Transform {
              translation 0 0 0.02
              rotation 1 0 0 1.5708
              children [
                DEF wheel1 Shape {
                  appearance PBRAppearance {
                    baseColor 0.8 0.8 0.8
                    transparency 0.12999999523162842
                    roughness 1
                    metalness 0
                    emissiveColor 0 1 0
                  }
                  geometry Cylinder {
                    height 0.02
                    radius 0.05
                  }
                }
              ]
            }
            physics Physics {
            }
            linearVelocity 0.415695186798564 7.167482536238638e-05 -0.27068570315008106
            angularVelocity 0.051172645772481096 0.15493762795995908 -0.20326331701439915
          }
        }
      ]
      name "wheel 3"
      boundingObject USE DUMMY
      physics Physics {
      }
    }
    DEF BODY_TRANS Transform {
      translation 0 -0.05 0
      scale 4 4 4
      children [
        Shape {
          appearance Appearance {
            material Material {
              ambientIntensity 1
              diffuseColor 0.792157 0.819608 0.933333
              shininess 0.4
              specularColor 0.396078 0.409804 0.466667
            }
            texture ImageTexture {
              url [
                "/home/jesus/Documents/Computational_Modeling/u3_real_exam_Duarte_Jesus/protos/anaranjado.png"
              ]
            }
          }
          geometry IndexedFaceSet {
            coord Coordinate {
              point [
                -0.043284 0.04 -0.009731, -0.043284 0.045 -0.009731, -0.043211 0.04 -0.013447, -0.043211 0.045 -0.013447, -0.04276 0.04 -0.006052, -0.04276 0.045 -0.006052, -0.042542 0.04 -0.017103, -0.042542 0.045 -0.017103, -0.041653 0.04 -0.002504, -0.041653 0.045 -0.002504, -0.041297 0.04 -0.010023, -0.041297 0.045 -0.010023, -0.041296 0.04 -0.020604, -0.041296 0.045 -0.020604, -0.041208 0.04 -0.013368, -0.041208 0.045 -0.013368, -0.040857 0.04 -0.006705, -0.040857 0.045 -0.006705, -0.040591 0.04 -0.016656, -0.040591 0.045 -0.016656, -0.039992 0 0.000821, -0.039992 0.04 0.000821, -0.039992 0.045 0.000821, -0.039897 0.04 -0.0035, -0.039897 0.045 -0.0035, -0.039504 0.04 -0.02386, -0.039504 0.045 -0.02386, -0.039462 0.04 -0.019806, -0.039462 0.045 -0.019806, -0.037848 0.04 -0.022738, -0.037848 0.045 -0.022738, -0.037213 0.04 -0.026787, -0.037213 0.045 -0.026787, -0.035792 0.04 -0.025378, -0.035792 0.045 -0.025378, -0.034482 0.04 -0.029308, -0.034482 0.045 -0.029308, -0.033344 0.04 -0.027659, -0.033344 0.045 -0.027659, -0.031382 0.04 -0.031358, -0.031382 0.045 -0.031358, -0.030566 0.04 -0.029524, -0.030566 0.045 -0.029524, -0.027994 0.04 -0.032885, -0.027994 0.045 -0.032885, -0.027527 0.04 -0.030927, -0.027527 0.045 -0.030927, -0.024404 0.04 -0.033848, -0.024404 0.045 -0.033848, -0.024306 0.04 -0.031831, -0.024306 0.045 -0.031831, -0.020707 0 -0.034223, -0.020707 0.04 -0.034223, -0.020707 0.045 -0.034223, -0.019285 0 0.035044, -0.019285 0.04 0.035044, -0.019285 0.045 0.035044, -0.017111 0.04 0.038059, -0.017111 0.045 0.038059, -0.014482 0.04 0.040686, -0.014482 0.045 0.040686, -0.013087 0.04 0.037918, -0.013087 0.045 0.037918, -0.011466 0.04 0.042857, -0.011466 0.045 0.042857, -0.010396 0.04 0.039989, -0.010396 0.045 0.039989, -0.00814 0.04 0.044516, -0.00814 0.045 0.044516, -0.007396 0.04 0.041578, -0.007396 0.045 0.041578, -0.004592 0.04 0.045621, -0.004592 0.045 0.045621, -0.004171 0.04 0.042639, -0.004171 0.045 0.042639, -0.000912 0.04 0.046142, -0.000912 0.045 0.046142, -0.000813 0.04 0.043142, -0.000813 0.045 0.043142, 0.002582 0.04 0.043072, 0.002582 0.045 0.043072, 0.002804 0.04 0.046065, 0.002804 0.045 0.046065, 0.005916 0.04 0.042432, 0.005916 0.045 0.042432, 0.00646 0.04 0.045394, 0.00646 0.045 0.045394, 0.009096 0.04 0.04124, 0.009096 0.045 0.04124, 0.00996 0.04 0.044145, 0.00996 0.045 0.044145, 0.012028 0.04 0.039529, 0.012028 0.045 0.039529, 0.013215 0.04 0.042351, 0.013215 0.045 0.042351, 0.014631 0.04 0.037349, 0.014631 0.045 0.037349, 0.016139 0.04 0.040057, 0.016139 0.045 0.040057, 0.018659 0.04 0.037325, 0.018659 0.045 0.037325, 0.019285 0 -0.035044, 0.019285 0.04 -0.035044, 0.019285 0.045 -0.035044, 0.020707 0 0.034223, 0.020707 0.04 0.034223, 0.020707 0.045 0.034223, 0.022979 0.04 -0.032802, 0.022979 0.045 -0.032802, 0.022995 0.04 -0.034821, 0.022995 0.045 -0.034821, 0.026235 0.04 -0.03203, 0.026235 0.045 -0.03203, 0.026621 0.04 -0.034006, 0.026621 0.045 -0.034006, 0.029328 0.04 -0.030753, 0.029328 0.045 -0.030753, 0.030069 0.04 -0.03262, 0.030069 0.045 -0.03262, 0.032181 0.04 -0.029004, 0.032181 0.045 -0.029004, 0.033251 0.04 -0.030698, 0.033251 0.045 -0.030698, 0.03472 0.04 -0.026825, 0.03472 0.045 -0.026825, 0.036083 0.04 -0.028291, 0.036083 0.045 -0.028291, 0.036884 0.04 -0.024272, 0.036884 0.045 -0.024272, 0.038492 0.04 -0.025461, 0.038492 0.045 -0.025461, 0.038616 0.04 -0.021409, 0.038616 0.045 -0.021409, 0.03972 0.04 -0.005134, 0.03972 0.045 -0.005134, 0.039874 0.04 -0.018308, 0.039874 0.045 -0.018308, 0.039992 0 -0.000821, 0.039992 0.04 -0.000821, 0.039992 0.045 -0.000821, 0.040416 0.04 -0.022281, 0.040416 0.045 -0.022281, 0.040547 0.04 -0.008376, 0.040547 0.045 -0.008376, 0.040625 0.04 -0.015047, 0.040625 0.045 -0.015047, 0.040851 0.04 -0.011708, 0.040851 0.045 -0.011708, 0.041516 0.04 -0.00421, 0.041516 0.045 -0.00421, 0.041805 0.04 -0.018834, 0.041805 0.045 -0.018834, 0.042476 0.04 -0.007801, 0.042476 0.045 -0.007801, 0.042623 0.04 -0.015208, 0.042623 0.045 -0.015208, 0.042848 0.04 -0.011499, 0.042848 0.045 -0.011499
              ]
            }
            coordIndex [
              53, 103, 52, -1, 52, 103, 102, -1, 52, 102, 51, -1, 51, 102, 101, -1, 21, 52, 20, -1, 20, 52, 51, -1, 20, 54, 21, -1, 21, 54, 55, -1, 21, 55, 22, -1, 22, 55, 56, -1, 105, 55, 104, -1, 104, 55, 54, -1, 104, 137, 105, -1, 105, 137, 138, -1, 105, 138, 106, -1, 106, 138, 139, -1, 102, 138, 101, -1, 101, 138, 137, -1, 137, 104, 101, -1, 101, 104, 54, -1, 101, 54, 51, -1, 51, 54, 20, -1, 45, 47, 49, -1, 49, 47, 52, -1, 49, 52, 23, -1, 52, 21, 23, -1, 23, 21, 8, -1, 23, 8, 16, -1, 16, 8, 4, -1, 16, 4, 10, -1, 10, 4, 0, -1, 10, 0, 14, -1, 14, 0, 2, -1, 14, 2, 18, -1, 18, 2, 6, -1, 18, 6, 27, -1, 27, 6, 12, -1, 27, 12, 29, -1, 29, 12, 25, -1, 29, 25, 33, -1, 33, 25, 31, -1, 33, 31, 37, -1, 37, 31, 35, -1, 37, 35, 41, -1, 41, 35, 39, -1, 41, 39, 45, -1, 45, 39, 43, -1, 45, 43, 47, -1, 105, 95, 55, -1, 55, 95, 61, -1, 55, 61, 57, -1, 105, 99, 95, -1, 95, 99, 97, -1, 95, 97, 91, -1, 91, 97, 93, -1, 91, 93, 87, -1, 87, 93, 89, -1, 87, 89, 83, -1, 83, 89, 85, -1, 83, 85, 79, -1, 79, 85, 81, -1, 79, 81, 77, -1, 77, 81, 75, -1, 77, 75, 73, -1, 73, 75, 71, -1, 73, 71, 69, -1, 69, 71, 67, -1, 69, 67, 65, -1, 65, 67, 63, -1, 65, 63, 61, -1, 61, 63, 59, -1, 61, 59, 57, -1, 53, 52, 47, -1, 53, 47, 48, -1, 48, 47, 43, -1, 48, 43, 44, -1, 44, 43, 39, -1, 44, 39, 40, -1, 40, 39, 35, -1, 40, 35, 36, -1, 36, 35, 31, -1, 36, 31, 32, -1, 32, 31, 25, -1, 32, 25, 26, -1, 26, 25, 12, -1, 26, 12, 13, -1, 13, 12, 6, -1, 13, 6, 7, -1, 7, 6, 2, -1, 7, 2, 3, -1, 3, 2, 0, -1, 3, 0, 1, -1, 1, 0, 4, -1, 1, 4, 5, -1, 5, 4, 8, -1, 5, 8, 9, -1, 9, 8, 21, -1, 9, 21, 22, -1, 56, 55, 57, -1, 56, 57, 58, -1, 58, 57, 59, -1, 58, 59, 60, -1, 60, 59, 63, -1, 60, 63, 64, -1, 64, 63, 67, -1, 64, 67, 68, -1, 68, 67, 71, -1, 68, 71, 72, -1, 72, 71, 75, -1, 72, 75, 76, -1, 76, 75, 81, -1, 76, 81, 82, -1, 82, 81, 85, -1, 82, 85, 86, -1, 86, 85, 89, -1, 86, 89, 90, -1, 90, 89, 93, -1, 90, 93, 94, -1, 94, 93, 97, -1, 94, 97, 98, -1, 98, 97, 99, -1, 98, 99, 100, -1, 100, 99, 105, -1, 100, 105, 106, -1, 139, 138, 148, -1, 139, 148, 149, -1, 149, 148, 152, -1, 149, 152, 153, -1, 153, 152, 156, -1, 153, 156, 157, -1, 157, 156, 154, -1, 157, 154, 155, -1, 155, 154, 150, -1, 155, 150, 151, -1, 151, 150, 140, -1, 151, 140, 141, -1, 141, 140, 129, -1, 141, 129, 130, -1, 130, 129, 125, -1, 130, 125, 126, -1, 126, 125, 121, -1, 126, 121, 122, -1, 122, 121, 117, -1, 122, 117, 118, -1, 118, 117, 113, -1, 118, 113, 114, -1, 114, 113, 109, -1, 114, 109, 110, -1, 110, 109, 102, -1, 110, 102, 103, -1, 9, 24, 17, -1, 62, 50, 24, -1, 103, 108, 110, -1, 110, 108, 112, -1, 62, 60, 66, -1, 66, 60, 64, -1, 66, 64, 70, -1, 70, 64, 68, -1, 70, 68, 74, -1, 74, 68, 72, -1, 74, 72, 78, -1, 78, 72, 76, -1, 78, 76, 80, -1, 80, 76, 82, -1, 80, 82, 84, -1, 84, 82, 86, -1, 84, 86, 88, -1, 88, 86, 90, -1, 88, 90, 92, -1, 92, 90, 94, -1, 92, 94, 96, -1, 96, 94, 98, -1, 96, 98, 100, -1, 9, 22, 24, -1, 24, 22, 56, -1, 24, 56, 62, -1, 62, 56, 58, -1, 62, 58, 60, -1, 134, 108, 96, -1, 96, 108, 103, -1, 96, 103, 62, -1, 62, 103, 53, -1, 62, 53, 50, -1, 50, 53, 48, -1, 50, 48, 46, -1, 46, 48, 44, -1, 46, 44, 42, -1, 42, 44, 40, -1, 42, 40, 38, -1, 38, 40, 36, -1, 38, 36, 34, -1, 34, 36, 32, -1, 34, 32, 30, -1, 30, 32, 26, -1, 30, 26, 28, -1, 28, 26, 13, -1, 28, 13, 19, -1, 19, 13, 7, -1, 19, 7, 15, -1, 15, 7, 3, -1, 15, 3, 11, -1, 11, 3, 1, -1, 11, 1, 17, -1, 17, 1, 5, -1, 17, 5, 9, -1, 100, 106, 96, -1, 96, 106, 139, -1, 96, 139, 134, -1, 134, 139, 149, -1, 134, 149, 143, -1, 143, 149, 153, -1, 143, 153, 147, -1, 147, 153, 157, -1, 147, 157, 145, -1, 145, 157, 155, -1, 145, 155, 136, -1, 136, 155, 151, -1, 136, 151, 132, -1, 132, 151, 141, -1, 132, 141, 128, -1, 128, 141, 130, -1, 128, 130, 124, -1, 124, 130, 126, -1, 124, 126, 120, -1, 120, 126, 122, -1, 120, 122, 116, -1, 116, 122, 118, -1, 116, 118, 112, -1, 112, 118, 114, -1, 112, 114, 110, -1, 142, 148, 133, -1, 133, 148, 138, -1, 133, 138, 107, -1, 138, 102, 107, -1, 107, 102, 109, -1, 107, 109, 111, -1, 111, 109, 113, -1, 111, 113, 115, -1, 115, 113, 117, -1, 115, 117, 119, -1, 119, 117, 121, -1, 119, 121, 123, -1, 123, 121, 125, -1, 123, 125, 127, -1, 127, 125, 129, -1, 127, 129, 131, -1, 131, 129, 140, -1, 131, 140, 135, -1, 135, 140, 150, -1, 135, 150, 144, -1, 144, 150, 154, -1, 144, 154, 146, -1, 146, 154, 156, -1, 146, 156, 142, -1, 142, 156, 152, -1, 142, 152, 148, -1, 96, 95, 92, -1, 92, 95, 91, -1, 92, 91, 88, -1, 88, 91, 87, -1, 88, 87, 84, -1, 84, 87, 83, -1, 84, 83, 80, -1, 80, 83, 79, -1, 80, 79, 78, -1, 78, 79, 77, -1, 78, 77, 74, -1, 74, 77, 73, -1, 74, 73, 70, -1, 70, 73, 69, -1, 70, 69, 66, -1, 66, 69, 65, -1, 66, 65, 62, -1, 62, 65, 61, -1, 61, 95, 62, -1, 62, 95, 96, -1, 108, 107, 112, -1, 112, 107, 111, -1, 112, 111, 116, -1, 116, 111, 115, -1, 116, 115, 120, -1, 120, 115, 119, -1, 120, 119, 124, -1, 124, 119, 123, -1, 124, 123, 128, -1, 128, 123, 127, -1, 128, 127, 132, -1, 132, 127, 131, -1, 132, 131, 136, -1, 136, 131, 135, -1, 136, 135, 145, -1, 145, 135, 144, -1, 145, 144, 147, -1, 147, 144, 146, -1, 147, 146, 143, -1, 143, 146, 142, -1, 143, 142, 134, -1, 134, 142, 133, -1, 133, 107, 134, -1, 134, 107, 108, -1, 24, 23, 17, -1, 17, 23, 16, -1, 17, 16, 11, -1, 11, 16, 10, -1, 11, 10, 15, -1, 15, 10, 14, -1, 15, 14, 19, -1, 19, 14, 18, -1, 19, 18, 28, -1, 28, 18, 27, -1, 28, 27, 30, -1, 30, 27, 29, -1, 30, 29, 34, -1, 34, 29, 33, -1, 34, 33, 38, -1, 38, 33, 37, -1, 38, 37, 42, -1, 42, 37, 41, -1, 42, 41, 46, -1, 46, 41, 45, -1, 46, 45, 50, -1, 50, 45, 49, -1, 49, 23, 50, -1, 50, 23, 24, -1
            ]
          }
        }
      ]
    }
    DEF left DistanceSensor {
      translation 0.15 0.04 0
      name "left_light"
      lookupTable [
        0 0 0
        0.2 65535 0
      ]
    }
    DEF right DistanceSensor {
      translation 0.1 0.04 0.1
      rotation 0 1 0 -0.9162996938995747
      name "right_light"
      lookupTable [
        0 0 0
        0.2 65535 0
      ]
    }
    DEF Post Transform {
      translation 0 0.21 0
      children [
        Transform {
          children [
            Shape {
              appearance PBRAppearance {
                baseColor 0.8 0 0
                roughness 1
              }
              geometry Cylinder {
                height 0.2
                radius 0.03
              }
            }
            DEF Gun HingeJoint {
              jointParameters HingeJointParameters {
                position 208.95711096947952
                axis 0 1 0
              }
              device [
                RotationalMotor {
                  name "motor_4"
                }
              ]
              endPoint Solid {
                rotation 0 -1 0 4.671189474626424
                children [
                  DEF Gun Transform {
                    translation 0.05 0.05 0
                    rotation 0 0 1 1.5708
                    children [
                      Shape {
                        appearance PBRAppearance {
                          baseColor 0 0 0
                        }
                        geometry DEF sensor Cylinder {
                          height 0.05
                          radius 0.02
                        }
                      }
                    ]
                  }
                ]
                name "1"
                boundingObject USE Gun
                physics Physics {
                }
                linearVelocity 0.05554637001840115 -0.046780635095571205 0.06937403864547018
                angularVelocity -0.4307703167946927 10.139459838801898 0.20452370531474967
              }
            }
            DEF Radar HingeJoint {
              jointParameters HingeJointParameters {
                position -5.144037959195984e-08
                axis 0 1 0
              }
              device [
                RotationalMotor {
                  name "motor_5"
                }
              ]
              endPoint Solid {
                rotation 0 -1 0 5.16191365590357e-08
                children [
                  DEF Radar Transform {
                    translation 0.05 0 0
                    rotation 0 0 1 1.5708
                    children [
                      Shape {
                        appearance PBRAppearance {
                          baseColor 0.9294117647058824 0.8313725490196079 0
                        }
                        geometry USE sensor
                      }
                    ]
                  }
                ]
                name "other"
                boundingObject USE Radar
                physics Physics {
                }
                linearVelocity 0.4069919192463269 -0.03226142813255306 -0.3316961110574608
                angularVelocity -0.1773510190624753 0.14591454262316356 -0.05065458613644691
              }
            }
          ]
        }
      ]
    }
  ]
  name "robot(1)"
  boundingObject USE BODY_TRANS
  physics Physics {
  }
  controller "u3_real_exam"
  linearVelocity 0.40432065287741986 -0.023665231704039072 -0.2990676344339012
  angularVelocity -0.1773511733817379 0.14591404035339872 -0.05065467771884136
}
DEF wall Solid {
  translation 0.06999999999999983 0.6 -4.119999999999999
  children [
    DEF wall Shape {
      appearance PBRAppearance {
      }
      geometry Box {
        size 2.9 1.2000000000000002 0.30000000000000004
      }
    }
  ]
  name "solid(1)"
  boundingObject USE wall
}
