#VRML_SIM R2019a utf8
WorldInfo {
}
Viewpoint {
  orientation -0.2922767027470194 -0.8281314767059307 -0.4783017732772742 2.1856671143383015
  position -1.0832494849036585 2.290333742572387 -0.6320994245857637
}
TexturedBackground {
}
TexturedBackgroundLight {
}
Floor {
}
DEF THREE_WHEELS Robot {
  translation 0.3239833889694553 0.05917324349326072 0.24057889048334666
  rotation -0.09782094904462085 -0.9552245310568785 0.2792439027000878 0.07175244012519952
  children [
    DEF SOLID1 Solid {
      children [
        DEF WHEEL1 HingeJoint {
          jointParameters HingeJointParameters {
            position -446.99176916795216
            axis 0 0 1
            anchor 0 0 0.1
          }
          device [
            RotationalMotor {
              name "wheel1"
              maxVelocity 30.4
              maxTorque 0.847
            }
            PositionSensor {
              name "first_ps"
              resolution 0.00385
            }
          ]
          endPoint Solid {
            translation 0 0 0.15000000000000002
            rotation 0 0 1 5.39757294897807
            children [
              DEF sr1 HingeJoint {
                jointParameters HingeJointParameters {
                  position -5142.46748433096
                  anchor 0 0.05 0.02
                }
                endPoint Solid {
                  translation 0 0.05 0.02
                  rotation -1 0 0 2.821903058058622
                  children [
                    DEF r1 Transform {
                      rotation 0 0 1 1.5708
                      children [
                        DEF SMALL_WHEEL_SHAPE Shape {
                          appearance PBRAppearance {
                            baseColor 0 0 0
                            roughness 1
                            metalness 0
                          }
                          geometry Cylinder {
                            height 0.02
                            radius 0.01
                          }
                        }
                      ]
                    }
                  ]
                  name "sr1"
                  boundingObject USE r1
                  physics Physics {
                    density -1
                    mass 0.1
                  }
                  linearVelocity 0.8258216364516513 -0.19615004941312952 0.22060863063851438
                  angularVelocity -9.258027594049487 7.681021542429912 -9.158066265018054
                }
              }
              DEF sr2 HingeJoint {
                jointParameters HingeJointParameters {
                  position -2499.774094768198
                  axis 0.707107 0.707107 0
                  anchor -0.03535 0.03535 0.02
                }
                endPoint Solid {
                  translation -0.03535 0.03535 0.02
                  rotation 0.7071067811865476 0.7071067811865476 0 0.9336574892772069
                  children [
                    DEF r2 Transform {
                      rotation 0 0 1 2.27
                      children [
                        USE SMALL_WHEEL_SHAPE
                      ]
                    }
                  ]
                  name "sr2"
                  boundingObject USE r2
                  physics Physics {
                    density -1
                    mass 0.1
                  }
                  linearVelocity 0.9046150732138141 0.10769090281079262 0.25128088656870173
                  angularVelocity -18.119166333013535 -2.6020051910813935 -10.176469753687142
                }
              }
              DEF sr3 HingeJoint {
                jointParameters HingeJointParameters {
                  position 3350.52353696923
                  anchor 0 -0.05 0.02
                }
                endPoint Solid {
                  translation 0 -0.05 0.02
                  rotation -1 0 0 4.69741706466917
                  children [
                    DEF r3 Transform {
                      rotation 0 0 1 1.5708
                      children [
                        USE SMALL_WHEEL_SHAPE
                      ]
                    }
                  ]
                  name "sr3"
                  boundingObject USE r3
                  physics Physics {
                    density -1
                    mass 0.1
                  }
                  linearVelocity 0.169447751022344 0.30387016211024653 0.2296791483992019
                  angularVelocity 12.046474895536942 -7.96258935604518 -7.554535401033779
                }
              }
              DEF sr4 HingeJoint {
                jointParameters HingeJointParameters {
                  position 4717.22919082933
                  axis 0.707107 0.707107 0
                  anchor 0.03535 -0.03535 0.02
                }
                endPoint Solid {
                  translation 0.03535 -0.03535 0.02
                  rotation 0.7071067811865476 0.7071067811865476 0 4.840210444640179
                  children [
                    DEF r4 Transform {
                      rotation 0 0 1 2.27
                      children [
                        USE SMALL_WHEEL_SHAPE
                      ]
                    }
                  ]
                  name "sr4"
                  boundingObject USE r4
                  physics Physics {
                    density -1
                    mass 0.1
                  }
                  linearVelocity 0.09071114210741699 0.0010853438880282784 0.1990018625112147
                  angularVelocity 16.767902407328133 3.4952203108353133 -6.895473208528478
                }
              }
              DEF sr5 HingeJoint {
                jointParameters HingeJointParameters {
                  position -5629.263616755828
                  axis 0 1 0
                  anchor -0.05 0 0.02
                }
                endPoint Solid {
                  translation -0.05 0 0.02
                  rotation 0 1 0 0.470418477081913
                  children [
                    DEF r5 Transform {
                      children [
                        USE SMALL_WHEEL_SHAPE
                      ]
                    }
                  ]
                  name "sr5"
                  boundingObject USE r5
                  physics Physics {
                    density -1
                    mass 0.1
                  }
                  linearVelocity 0.7450902177173425 0.3800652403867639 0.266647990257779
                  angularVelocity -12.196059311876443 -17.271675149265274 -9.785656377244495
                }
              }
              DEF sr6 HingeJoint {
                jointParameters HingeJointParameters {
                  position 6846.662972322176
                  axis 0 1 0
                  anchor 0.05 0 0.02
                }
                endPoint Solid {
                  translation 0.05 0 0.02
                  rotation 0 -1 0 2.009012503573413
                  children [
                    DEF r6 Transform {
                      children [
                        USE SMALL_WHEEL_SHAPE
                      ]
                    }
                  ]
                  name "sr6"
                  boundingObject USE r6
                  physics Physics {
                    density -1
                    mass 0.1
                  }
                  linearVelocity 0.2501459564115895 -0.27215290376823864 0.18364026946262904
                  angularVelocity 5.648498712946032 7.814670683396794 -7.704711592807536
                }
              }
              DEF sr7 HingeJoint {
                jointParameters HingeJointParameters {
                  position -3034.858993996596
                  axis -0.707107 0.707107 0
                  anchor -0.03535 -0.03535 0.02
                }
                endPoint Solid {
                  translation -0.03535 -0.03535 0.02
                  rotation -0.7071067811865475 0.7071067811865475 0 6.202694678323926
                  children [
                    DEF r7 Transform {
                      rotation 0 0 1 0.76
                      children [
                        USE SMALL_WHEEL_SHAPE
                      ]
                    }
                  ]
                  name "sr7"
                  boundingObject USE r7
                  physics Physics {
                    density -1
                    mass 0.1
                  }
                  linearVelocity 0.4405228175557747 0.4612554061800259 0.25768434395739553
                  angularVelocity 5.210494891357101 -25.94795452946846 -8.051965284915763
                }
              }
              DEF sr8 HingeJoint {
                jointParameters HingeJointParameters {
                  position 5990.890519855091
                  axis -0.707107 0.707107 0
                  anchor 0.03535 0.03535 0.02
                }
                endPoint Solid {
                  translation 0.03535 0.03535 0.02
                  rotation 0.7071067811865475 -0.7071067811865475 0 3.268263194234456
                  children [
                    DEF r8 Transform {
                      rotation 0 0 1 0.76
                      children [
                        USE SMALL_WHEEL_SHAPE
                      ]
                    }
                  ]
                  name "sr8"
                  boundingObject USE r8
                  physics Physics {
                    density -1
                    mass 0.1
                  }
                  linearVelocity 0.5546940583311651 -0.3534343940877359 0.19259403121648813
                  angularVelocity -1.6397809587733745 13.200290540926906 -8.423267082197217
                }
              }
              DEF WHEEL_TRANS Transform {
                translation 0 0 0.02
                rotation 1 0 0 1.5708
                children [
                  DEF WHEEL_SHAPE Shape {
                    appearance PBRAppearance {
                      baseColor 0.5333333333333333 0.5411764705882353 0.5215686274509804
                      roughness 1
                      metalness 0
                    }
                    geometry Cylinder {
                      height 0.02
                      radius 0.05
                      subdivision 20
                    }
                  }
                ]
              }
            ]
            boundingObject Transform {
              translation 0 0 0.02
              rotation 1 0 0 1.5708
              children [
                DEF wheel1 Shape {
                  appearance PBRAppearance {
                    baseColor 0.8 0.8 0.8
                    transparency 0.12999999523162842
                    roughness 1
                    metalness 0
                    emissiveColor 0 1 0
                  }
                  geometry Cylinder {
                    height 0.02
                    radius 0.05
                  }
                }
              ]
            }
            physics Physics {
            }
            linearVelocity 0.49761747968879494 0.053983412025755545 0.2251456817783528
            angularVelocity 0.3477989320787849 0.6757388170857493 -7.731977024028177
          }
        }
      ]
      name "wheel 1"
      boundingObject DEF DUMMY Sphere {
        radius 0.01
      }
      physics Physics {
      }
    }
    DEF SOLID2 Solid {
      rotation 0 1 0 2.09
      children [
        DEF WHEEL2 HingeJoint {
          jointParameters HingeJointParameters {
            position 380.30188112615673
            axis 0 0 1
            anchor 0 0 0.1
          }
          device [
            RotationalMotor {
              name "wheel2"
              maxVelocity 30.4
              maxTorque 0.847
            }
            PositionSensor {
              name "second_ps"
              resolution 0.00385
            }
          ]
          endPoint Solid {
            translation 0 0 0.14999999999999997
            rotation 0 0 1 3.313168505380762
            children [
              DEF sr1 HingeJoint {
                jointParameters HingeJointParameters {
                  position -5545.086789253954
                  anchor 0 0.05 0.02
                }
                endPoint Solid {
                  translation 0 0.05 0.02
                  rotation -1 0 0 3.317348321558339
                  children [
                    USE r1
                  ]
                  name "sr1"
                  boundingObject USE r1
                  physics Physics {
                    density -1
                    mass 0.1
                  }
                  linearVelocity 0.16506680522197834 -0.0881803719436911 -0.24984785849071292
                  angularVelocity -6.567230131295835 -2.6019370582223837 -33.445844664867515
                }
              }
              DEF sr2 HingeJoint {
                jointParameters HingeJointParameters {
                  position -4076.4365873072966
                  axis 0.707107 0.707107 0
                  anchor -0.03535 0.03535 0.02
                }
                endPoint Solid {
                  translation -0.03535 0.03535 0.02
                  rotation -0.7071067811865475 -0.7071067811865475 0 4.93250825492454
                  children [
                    USE r2
                  ]
                  name "sr2"
                  boundingObject USE r2
                  physics Physics {
                    density -1
                    mass 0.1
                  }
                  linearVelocity 0.18234408851000122 0.2109800287978871 -0.14725749131367694
                  angularVelocity -2.057705405549342 17.75394843237414 -23.632947919647023
                }
              }
              DEF sr3 HingeJoint {
                jointParameters HingeJointParameters {
                  position 2731.507390157484
                  anchor 0 -0.05 0.02
                }
                endPoint Solid {
                  translation 0 -0.05 0.02
                  rotation 1 0 0 4.604966841543693
                  children [
                    USE r3
                  ]
                  name "sr3"
                  boundingObject USE r3
                  physics Physics {
                    density -1
                    mass 0.1
                  }
                  linearVelocity 0.5317715987247861 -0.030160343085156915 0.48879242300909104
                  angularVelocity 15.68524782421138 3.139011229851298 13.883958537733252
                }
              }
              DEF sr4 HingeJoint {
                jointParameters HingeJointParameters {
                  position 6071.940425956419
                  axis 0.707107 0.707107 0
                  anchor 0.03535 -0.03535 0.02
                }
                endPoint Solid {
                  translation 0.03535 -0.03535 0.02
                  rotation 0.7071067811865475 0.7071067811865475 0 2.383419220938412
                  children [
                    USE r4
                  ]
                  name "sr4"
                  boundingObject USE r4
                  physics Physics {
                    density -1
                    mass 0.1
                  }
                  linearVelocity 0.5144728941143117 -0.3292379243413384 0.386166115853561
                  angularVelocity 13.33048988945318 -9.707951470484874 8.011853133876988
                }
              }
              DEF sr5 HingeJoint {
                jointParameters HingeJointParameters {
                  position -2025.0828986678166
                  axis 0 1 0
                  anchor -0.05 0 0.02
                }
                endPoint Solid {
                  translation -0.05 0 0.02
                  rotation 0 -1 0 1.8972297559897617
                  children [
                    USE r5
                  ]
                  name "sr5"
                  boundingObject USE r5
                  physics Physics {
                    density -1
                    mass 0.1
                  }
                  linearVelocity 0.2968783130752055 0.35193872243765356 0.11152662323257781
                  angularVelocity 5.601384029742842 24.629045271661965 -6.014872829412511
                }
              }
              DEF sr6 HingeJoint {
                jointParameters HingeJointParameters {
                  position 3875.7442950298314
                  axis 0 1 0
                  anchor 0.05 0 0.02
                }
                endPoint Solid {
                  translation 0.05 0 0.02
                  rotation 0 1 0 5.302145807206122
                  children [
                    USE r6
                  ]
                  name "sr6"
                  boundingObject USE r6
                  physics Physics {
                    density -1
                    mass 0.1
                  }
                  linearVelocity 0.3999313549436106 -0.4701039493148792 0.12735669252799342
                  angularVelocity 8.128162972077394 -9.599063540938726 -3.0310290808791835
                }
              }
              DEF sr7 HingeJoint {
                jointParameters HingeJointParameters {
                  position -1711.2201893083472
                  axis -0.707107 0.707107 0
                  anchor -0.03535 -0.03535 0.02
                }
                endPoint Solid {
                  translation -0.03535 -0.03535 0.02
                  rotation 0.7071067811865476 -0.7071067811865476 0 2.1937857554997224
                  children [
                    USE r7
                  ]
                  name "sr7"
                  boundingObject USE r7
                  physics Physics {
                    density -1
                    mass 0.1
                  }
                  linearVelocity 0.4416155358707179 0.25196058056058096 0.37497577968596507
                  angularVelocity 12.180031052001361 15.63558431649895 6.9837329196246465
                }
              }
              DEF sr8 HingeJoint {
                jointParameters HingeJointParameters {
                  position 2757.6394083637906
                  axis -0.707107 0.707107 0
                  anchor 0.03535 0.03535 0.02
                }
                endPoint Solid {
                  translation 0.03535 0.03535 0.02
                  rotation -0.7071067811865475 0.7071067811865475 0 5.604243819131731
                  children [
                    USE r8
                  ]
                  name "sr8"
                  boundingObject USE r8
                  physics Physics {
                    density -1
                    mass 0.1
                  }
                  linearVelocity 0.25519508633847104 -0.3700940744031763 -0.13609034762194006
                  angularVelocity 5.425636360498006 -4.992336722856173 -8.351541356924809
                }
              }
              USE WHEEL_TRANS
            ]
            boundingObject Transform {
              translation 0 0 0.02
              rotation 1 0 0 1.5708
              children [
                DEF wheel1 Shape {
                  appearance PBRAppearance {
                    baseColor 0.8 0.8 0.8
                    transparency 0.12999999523162842
                    roughness 1
                    metalness 0
                    emissiveColor 0 1 0
                  }
                  geometry Cylinder {
                    height 0.02
                    radius 0.05
                  }
                }
              ]
            }
            physics Physics {
            }
            linearVelocity 0.34840684061169913 -0.059051752545184216 0.1194469405505871
            angularVelocity 6.961650689034188 0.8247404076388583 -3.572170873609753
          }
        }
      ]
      name "wheel 2"
      boundingObject USE DUMMY
      physics Physics {
      }
    }
    DEF SOLID3 Solid {
      rotation 0 1 0 4.18
      children [
        DEF WHEEL3 HingeJoint {
          jointParameters HingeJointParameters {
            position 167.25750383592813
            axis 0 0 1
            anchor 0 0 0.1
          }
          device [
            RotationalMotor {
              name "wheel3"
              maxVelocity 30.4
              maxTorque 0.847
            }
            PositionSensor {
              name "third_ps"
              resolution 0.00385
            }
          ]
          endPoint Solid {
            translation 0 0 0.15000000000000002
            rotation 0 0 0.9999999999999999 3.898595289258338
            children [
              DEF sr1 HingeJoint {
                jointParameters HingeJointParameters {
                  position -153.6443022847788
                  anchor 0 0.05 0.02
                }
                endPoint Solid {
                  translation 0 0.05 0.02
                  rotation -0.9999999999999999 0 0 2.8478549124687276
                  children [
                    USE r1
                  ]
                  name "sr1"
                  boundingObject USE r1
                  physics Physics {
                    density -1
                    mass 0.1
                  }
                  linearVelocity 0.3682023818381466 -0.03401063207164348 0.29044424589194745
                  angularVelocity 0.9451875366683908 0.34432728258513806 0.2794167870934802
                }
              }
              DEF sr2 HingeJoint {
                jointParameters HingeJointParameters {
                  position 382.04122083353855
                  axis 0.707107 0.707107 0
                  anchor -0.03535 0.03535 0.02
                }
                endPoint Solid {
                  translation -0.03535 0.03535 0.02
                  rotation 0.7071067811865476 0.7071067811865476 0 5.050102402763357
                  children [
                    USE r2
                  ]
                  name "sr2"
                  boundingObject USE r2
                  physics Physics {
                    density -1
                    mass 0.1
                  }
                  linearVelocity 0.3571347355015645 -0.047861169138026224 0.3231488148906463
                  angularVelocity 0.7698304779563343 0.031573070010855867 0.5356224326758626
                }
              }
              DEF sr3 HingeJoint {
                jointParameters HingeJointParameters {
                  position 636.1969782484584
                  anchor 0 -0.05 0.02
                }
                endPoint Solid {
                  translation 0 -0.05 0.02
                  rotation -1 0 0 4.687923083859385
                  children [
                    USE r3
                  ]
                  name "sr3"
                  boundingObject USE r3
                  physics Physics {
                    density -1
                    mass 0.1
                  }
                  linearVelocity 0.2922982898337031 0.03077337149504728 0.3185094826699325
                  angularVelocity 0.9451871106182246 0.34432798599932724 0.27941736075571866
                }
              }
              DEF sr4 HingeJoint {
                jointParameters HingeJointParameters {
                  position -236.32292438763355
                  axis 0.707107 0.707107 0
                  anchor 0.03535 -0.03535 0.02
                }
                endPoint Solid {
                  translation 0.03535 -0.03535 0.02
                  rotation 0.7071067811865475 0.7071067811865475 0 2.4381172851907373
                  children [
                    USE r4
                  ]
                  name "sr4"
                  boundingObject USE r4
                  physics Physics {
                    density -1
                    mass 0.1
                  }
                  linearVelocity 0.3033659361702821 0.04462390856143923 0.28580491367123145
                  angularVelocity 0.7703208601684062 0.01003660441171796 0.5357606802034914
                }
              }
              DEF sr5 HingeJoint {
                jointParameters HingeJointParameters {
                  position 518.7539767505723
                  axis 0 1 0
                  anchor -0.05 0 0.02
                }
                endPoint Solid {
                  translation -0.05 0 0.02
                  rotation 0 1 0 3.532781561846201
                  children [
                    USE r5
                  ]
                  name "sr5"
                  boundingObject USE r5
                  physics Physics {
                    density -1
                    mass 0.1
                  }
                  linearVelocity 0.3303243148204598 -0.03463333126270415 0.34491959668649214
                  angularVelocity 0.5755793397785046 0.3291711603576618 0.7967088985527022
                }
              }
              DEF sr6 HingeJoint {
                jointParameters HingeJointParameters {
                  position -1567.2455521691438
                  axis 0 1 0
                  anchor 0.05 0 0.02
                }
                endPoint Solid {
                  translation 0.05 0 0.02
                  rotation 0 1 0 3.5507746257527986
                  children [
                    USE r6
                  ]
                  name "sr6"
                  boundingObject USE r6
                  physics Physics {
                    density -1
                    mass 0.1
                  }
                  linearVelocity 0.3301763568513829 0.031396070686110666 0.26403413187539304
                  angularVelocity 0.5755793397785256 0.32917116035768895 0.7967088985527295
                }
              }
              DEF sr7 HingeJoint {
                jointParameters HingeJointParameters {
                  position -76.89640818643181
                  axis -0.707107 0.707107 0
                  anchor -0.03535 -0.03535 0.02
                }
                endPoint Solid {
                  translation -0.03535 -0.03535 0.02
                  rotation 0.7071067811865475 -0.7071067811865475 0 1.4981845002767753
                  children [
                    USE r7
                  ]
                  name "sr7"
                  boundingObject USE r7
                  physics Physics {
                    density -1
                    mass 0.1
                  }
                  linearVelocity 0.303470542454405 -0.002058878616375921 0.3429909372926761
                  angularVelocity 0.7530920033745218 0.6546032635393038 0.537002325729657
                }
              }
              DEF sr8 HingeJoint {
                jointParameters HingeJointParameters {
                  position 123.49386910663884
                  axis -0.707107 0.707107 0
                  anchor 0.03535 0.03535 0.02
                }
                endPoint Solid {
                  translation 0.03535 0.03535 0.02
                  rotation 0.7071067811865476 -0.7071067811865476 0 2.1698370369528894
                  children [
                    USE r8
                  ]
                  name "sr8"
                  boundingObject USE r8
                  physics Physics {
                    density -1
                    mass 0.1
                  }
                  linearVelocity 0.3570828399091176 -0.001152920919822691 0.26589278751247436
                  angularVelocity 26.170895509750622 1.015513598332115 -35.210542150091186
                }
              }
              USE WHEEL_TRANS
            ]
            boundingObject Transform {
              translation 0 0 0.02
              rotation 1 0 0 1.5708
              children [
                DEF wheel1 Shape {
                  appearance PBRAppearance {
                    baseColor 0.8 0.8 0.8
                    transparency 0.12999999523162842
                    roughness 1
                    metalness 0
                    emissiveColor 0 1 0
                  }
                  geometry Cylinder {
                    height 0.02
                    radius 0.05
                  }
                }
              ]
            }
            physics Physics {
            }
            linearVelocity 0.3302510887138299 -0.001618881452435261 0.3044771661737799
            angularVelocity 0.7567077838632575 0.6545673395166417 0.5317063674157178
          }
        }
      ]
      name "wheel 3"
      boundingObject USE DUMMY
      physics Physics {
      }
    }
    DEF BODY_TRANS Transform {
      translation 0 -0.05 0
      scale 4 4 4
      children [
        Shape {
          appearance Appearance {
            material Material {
              ambientIntensity 1
              diffuseColor 0.792157 0.819608 0.933333
              shininess 0.4
              specularColor 0.396078 0.409804 0.466667
            }
            texture ImageTexture {
              url [
                "/home/jesus/Documents/Computational_Modeling/u3_real_exam_Duarte_Jesus/protos/anaranjado.png"
              ]
            }
          }
          geometry IndexedFaceSet {
            coord Coordinate {
              point [
                -0.043284 0.04 -0.009731, -0.043284 0.045 -0.009731, -0.043211 0.04 -0.013447, -0.043211 0.045 -0.013447, -0.04276 0.04 -0.006052, -0.04276 0.045 -0.006052, -0.042542 0.04 -0.017103, -0.042542 0.045 -0.017103, -0.041653 0.04 -0.002504, -0.041653 0.045 -0.002504, -0.041297 0.04 -0.010023, -0.041297 0.045 -0.010023, -0.041296 0.04 -0.020604, -0.041296 0.045 -0.020604, -0.041208 0.04 -0.013368, -0.041208 0.045 -0.013368, -0.040857 0.04 -0.006705, -0.040857 0.045 -0.006705, -0.040591 0.04 -0.016656, -0.040591 0.045 -0.016656, -0.039992 0 0.000821, -0.039992 0.04 0.000821, -0.039992 0.045 0.000821, -0.039897 0.04 -0.0035, -0.039897 0.045 -0.0035, -0.039504 0.04 -0.02386, -0.039504 0.045 -0.02386, -0.039462 0.04 -0.019806, -0.039462 0.045 -0.019806, -0.037848 0.04 -0.022738, -0.037848 0.045 -0.022738, -0.037213 0.04 -0.026787, -0.037213 0.045 -0.026787, -0.035792 0.04 -0.025378, -0.035792 0.045 -0.025378, -0.034482 0.04 -0.029308, -0.034482 0.045 -0.029308, -0.033344 0.04 -0.027659, -0.033344 0.045 -0.027659, -0.031382 0.04 -0.031358, -0.031382 0.045 -0.031358, -0.030566 0.04 -0.029524, -0.030566 0.045 -0.029524, -0.027994 0.04 -0.032885, -0.027994 0.045 -0.032885, -0.027527 0.04 -0.030927, -0.027527 0.045 -0.030927, -0.024404 0.04 -0.033848, -0.024404 0.045 -0.033848, -0.024306 0.04 -0.031831, -0.024306 0.045 -0.031831, -0.020707 0 -0.034223, -0.020707 0.04 -0.034223, -0.020707 0.045 -0.034223, -0.019285 0 0.035044, -0.019285 0.04 0.035044, -0.019285 0.045 0.035044, -0.017111 0.04 0.038059, -0.017111 0.045 0.038059, -0.014482 0.04 0.040686, -0.014482 0.045 0.040686, -0.013087 0.04 0.037918, -0.013087 0.045 0.037918, -0.011466 0.04 0.042857, -0.011466 0.045 0.042857, -0.010396 0.04 0.039989, -0.010396 0.045 0.039989, -0.00814 0.04 0.044516, -0.00814 0.045 0.044516, -0.007396 0.04 0.041578, -0.007396 0.045 0.041578, -0.004592 0.04 0.045621, -0.004592 0.045 0.045621, -0.004171 0.04 0.042639, -0.004171 0.045 0.042639, -0.000912 0.04 0.046142, -0.000912 0.045 0.046142, -0.000813 0.04 0.043142, -0.000813 0.045 0.043142, 0.002582 0.04 0.043072, 0.002582 0.045 0.043072, 0.002804 0.04 0.046065, 0.002804 0.045 0.046065, 0.005916 0.04 0.042432, 0.005916 0.045 0.042432, 0.00646 0.04 0.045394, 0.00646 0.045 0.045394, 0.009096 0.04 0.04124, 0.009096 0.045 0.04124, 0.00996 0.04 0.044145, 0.00996 0.045 0.044145, 0.012028 0.04 0.039529, 0.012028 0.045 0.039529, 0.013215 0.04 0.042351, 0.013215 0.045 0.042351, 0.014631 0.04 0.037349, 0.014631 0.045 0.037349, 0.016139 0.04 0.040057, 0.016139 0.045 0.040057, 0.018659 0.04 0.037325, 0.018659 0.045 0.037325, 0.019285 0 -0.035044, 0.019285 0.04 -0.035044, 0.019285 0.045 -0.035044, 0.020707 0 0.034223, 0.020707 0.04 0.034223, 0.020707 0.045 0.034223, 0.022979 0.04 -0.032802, 0.022979 0.045 -0.032802, 0.022995 0.04 -0.034821, 0.022995 0.045 -0.034821, 0.026235 0.04 -0.03203, 0.026235 0.045 -0.03203, 0.026621 0.04 -0.034006, 0.026621 0.045 -0.034006, 0.029328 0.04 -0.030753, 0.029328 0.045 -0.030753, 0.030069 0.04 -0.03262, 0.030069 0.045 -0.03262, 0.032181 0.04 -0.029004, 0.032181 0.045 -0.029004, 0.033251 0.04 -0.030698, 0.033251 0.045 -0.030698, 0.03472 0.04 -0.026825, 0.03472 0.045 -0.026825, 0.036083 0.04 -0.028291, 0.036083 0.045 -0.028291, 0.036884 0.04 -0.024272, 0.036884 0.045 -0.024272, 0.038492 0.04 -0.025461, 0.038492 0.045 -0.025461, 0.038616 0.04 -0.021409, 0.038616 0.045 -0.021409, 0.03972 0.04 -0.005134, 0.03972 0.045 -0.005134, 0.039874 0.04 -0.018308, 0.039874 0.045 -0.018308, 0.039992 0 -0.000821, 0.039992 0.04 -0.000821, 0.039992 0.045 -0.000821, 0.040416 0.04 -0.022281, 0.040416 0.045 -0.022281, 0.040547 0.04 -0.008376, 0.040547 0.045 -0.008376, 0.040625 0.04 -0.015047, 0.040625 0.045 -0.015047, 0.040851 0.04 -0.011708, 0.040851 0.045 -0.011708, 0.041516 0.04 -0.00421, 0.041516 0.045 -0.00421, 0.041805 0.04 -0.018834, 0.041805 0.045 -0.018834, 0.042476 0.04 -0.007801, 0.042476 0.045 -0.007801, 0.042623 0.04 -0.015208, 0.042623 0.045 -0.015208, 0.042848 0.04 -0.011499, 0.042848 0.045 -0.011499
              ]
            }
            coordIndex [
              53, 103, 52, -1, 52, 103, 102, -1, 52, 102, 51, -1, 51, 102, 101, -1, 21, 52, 20, -1, 20, 52, 51, -1, 20, 54, 21, -1, 21, 54, 55, -1, 21, 55, 22, -1, 22, 55, 56, -1, 105, 55, 104, -1, 104, 55, 54, -1, 104, 137, 105, -1, 105, 137, 138, -1, 105, 138, 106, -1, 106, 138, 139, -1, 102, 138, 101, -1, 101, 138, 137, -1, 137, 104, 101, -1, 101, 104, 54, -1, 101, 54, 51, -1, 51, 54, 20, -1, 45, 47, 49, -1, 49, 47, 52, -1, 49, 52, 23, -1, 52, 21, 23, -1, 23, 21, 8, -1, 23, 8, 16, -1, 16, 8, 4, -1, 16, 4, 10, -1, 10, 4, 0, -1, 10, 0, 14, -1, 14, 0, 2, -1, 14, 2, 18, -1, 18, 2, 6, -1, 18, 6, 27, -1, 27, 6, 12, -1, 27, 12, 29, -1, 29, 12, 25, -1, 29, 25, 33, -1, 33, 25, 31, -1, 33, 31, 37, -1, 37, 31, 35, -1, 37, 35, 41, -1, 41, 35, 39, -1, 41, 39, 45, -1, 45, 39, 43, -1, 45, 43, 47, -1, 105, 95, 55, -1, 55, 95, 61, -1, 55, 61, 57, -1, 105, 99, 95, -1, 95, 99, 97, -1, 95, 97, 91, -1, 91, 97, 93, -1, 91, 93, 87, -1, 87, 93, 89, -1, 87, 89, 83, -1, 83, 89, 85, -1, 83, 85, 79, -1, 79, 85, 81, -1, 79, 81, 77, -1, 77, 81, 75, -1, 77, 75, 73, -1, 73, 75, 71, -1, 73, 71, 69, -1, 69, 71, 67, -1, 69, 67, 65, -1, 65, 67, 63, -1, 65, 63, 61, -1, 61, 63, 59, -1, 61, 59, 57, -1, 53, 52, 47, -1, 53, 47, 48, -1, 48, 47, 43, -1, 48, 43, 44, -1, 44, 43, 39, -1, 44, 39, 40, -1, 40, 39, 35, -1, 40, 35, 36, -1, 36, 35, 31, -1, 36, 31, 32, -1, 32, 31, 25, -1, 32, 25, 26, -1, 26, 25, 12, -1, 26, 12, 13, -1, 13, 12, 6, -1, 13, 6, 7, -1, 7, 6, 2, -1, 7, 2, 3, -1, 3, 2, 0, -1, 3, 0, 1, -1, 1, 0, 4, -1, 1, 4, 5, -1, 5, 4, 8, -1, 5, 8, 9, -1, 9, 8, 21, -1, 9, 21, 22, -1, 56, 55, 57, -1, 56, 57, 58, -1, 58, 57, 59, -1, 58, 59, 60, -1, 60, 59, 63, -1, 60, 63, 64, -1, 64, 63, 67, -1, 64, 67, 68, -1, 68, 67, 71, -1, 68, 71, 72, -1, 72, 71, 75, -1, 72, 75, 76, -1, 76, 75, 81, -1, 76, 81, 82, -1, 82, 81, 85, -1, 82, 85, 86, -1, 86, 85, 89, -1, 86, 89, 90, -1, 90, 89, 93, -1, 90, 93, 94, -1, 94, 93, 97, -1, 94, 97, 98, -1, 98, 97, 99, -1, 98, 99, 100, -1, 100, 99, 105, -1, 100, 105, 106, -1, 139, 138, 148, -1, 139, 148, 149, -1, 149, 148, 152, -1, 149, 152, 153, -1, 153, 152, 156, -1, 153, 156, 157, -1, 157, 156, 154, -1, 157, 154, 155, -1, 155, 154, 150, -1, 155, 150, 151, -1, 151, 150, 140, -1, 151, 140, 141, -1, 141, 140, 129, -1, 141, 129, 130, -1, 130, 129, 125, -1, 130, 125, 126, -1, 126, 125, 121, -1, 126, 121, 122, -1, 122, 121, 117, -1, 122, 117, 118, -1, 118, 117, 113, -1, 118, 113, 114, -1, 114, 113, 109, -1, 114, 109, 110, -1, 110, 109, 102, -1, 110, 102, 103, -1, 9, 24, 17, -1, 62, 50, 24, -1, 103, 108, 110, -1, 110, 108, 112, -1, 62, 60, 66, -1, 66, 60, 64, -1, 66, 64, 70, -1, 70, 64, 68, -1, 70, 68, 74, -1, 74, 68, 72, -1, 74, 72, 78, -1, 78, 72, 76, -1, 78, 76, 80, -1, 80, 76, 82, -1, 80, 82, 84, -1, 84, 82, 86, -1, 84, 86, 88, -1, 88, 86, 90, -1, 88, 90, 92, -1, 92, 90, 94, -1, 92, 94, 96, -1, 96, 94, 98, -1, 96, 98, 100, -1, 9, 22, 24, -1, 24, 22, 56, -1, 24, 56, 62, -1, 62, 56, 58, -1, 62, 58, 60, -1, 134, 108, 96, -1, 96, 108, 103, -1, 96, 103, 62, -1, 62, 103, 53, -1, 62, 53, 50, -1, 50, 53, 48, -1, 50, 48, 46, -1, 46, 48, 44, -1, 46, 44, 42, -1, 42, 44, 40, -1, 42, 40, 38, -1, 38, 40, 36, -1, 38, 36, 34, -1, 34, 36, 32, -1, 34, 32, 30, -1, 30, 32, 26, -1, 30, 26, 28, -1, 28, 26, 13, -1, 28, 13, 19, -1, 19, 13, 7, -1, 19, 7, 15, -1, 15, 7, 3, -1, 15, 3, 11, -1, 11, 3, 1, -1, 11, 1, 17, -1, 17, 1, 5, -1, 17, 5, 9, -1, 100, 106, 96, -1, 96, 106, 139, -1, 96, 139, 134, -1, 134, 139, 149, -1, 134, 149, 143, -1, 143, 149, 153, -1, 143, 153, 147, -1, 147, 153, 157, -1, 147, 157, 145, -1, 145, 157, 155, -1, 145, 155, 136, -1, 136, 155, 151, -1, 136, 151, 132, -1, 132, 151, 141, -1, 132, 141, 128, -1, 128, 141, 130, -1, 128, 130, 124, -1, 124, 130, 126, -1, 124, 126, 120, -1, 120, 126, 122, -1, 120, 122, 116, -1, 116, 122, 118, -1, 116, 118, 112, -1, 112, 118, 114, -1, 112, 114, 110, -1, 142, 148, 133, -1, 133, 148, 138, -1, 133, 138, 107, -1, 138, 102, 107, -1, 107, 102, 109, -1, 107, 109, 111, -1, 111, 109, 113, -1, 111, 113, 115, -1, 115, 113, 117, -1, 115, 117, 119, -1, 119, 117, 121, -1, 119, 121, 123, -1, 123, 121, 125, -1, 123, 125, 127, -1, 127, 125, 129, -1, 127, 129, 131, -1, 131, 129, 140, -1, 131, 140, 135, -1, 135, 140, 150, -1, 135, 150, 144, -1, 144, 150, 154, -1, 144, 154, 146, -1, 146, 154, 156, -1, 146, 156, 142, -1, 142, 156, 152, -1, 142, 152, 148, -1, 96, 95, 92, -1, 92, 95, 91, -1, 92, 91, 88, -1, 88, 91, 87, -1, 88, 87, 84, -1, 84, 87, 83, -1, 84, 83, 80, -1, 80, 83, 79, -1, 80, 79, 78, -1, 78, 79, 77, -1, 78, 77, 74, -1, 74, 77, 73, -1, 74, 73, 70, -1, 70, 73, 69, -1, 70, 69, 66, -1, 66, 69, 65, -1, 66, 65, 62, -1, 62, 65, 61, -1, 61, 95, 62, -1, 62, 95, 96, -1, 108, 107, 112, -1, 112, 107, 111, -1, 112, 111, 116, -1, 116, 111, 115, -1, 116, 115, 120, -1, 120, 115, 119, -1, 120, 119, 124, -1, 124, 119, 123, -1, 124, 123, 128, -1, 128, 123, 127, -1, 128, 127, 132, -1, 132, 127, 131, -1, 132, 131, 136, -1, 136, 131, 135, -1, 136, 135, 145, -1, 145, 135, 144, -1, 145, 144, 147, -1, 147, 144, 146, -1, 147, 146, 143, -1, 143, 146, 142, -1, 143, 142, 134, -1, 134, 142, 133, -1, 133, 107, 134, -1, 134, 107, 108, -1, 24, 23, 17, -1, 17, 23, 16, -1, 17, 16, 11, -1, 11, 16, 10, -1, 11, 10, 15, -1, 15, 10, 14, -1, 15, 14, 19, -1, 19, 14, 18, -1, 19, 18, 28, -1, 28, 18, 27, -1, 28, 27, 30, -1, 30, 27, 29, -1, 30, 29, 34, -1, 34, 29, 33, -1, 34, 33, 38, -1, 38, 33, 37, -1, 38, 37, 42, -1, 42, 37, 41, -1, 42, 41, 46, -1, 46, 41, 45, -1, 46, 45, 50, -1, 50, 45, 49, -1, 49, 23, 50, -1, 50, 23, 24, -1
            ]
          }
        }
      ]
    }
    DEF left DistanceSensor {
      translation 0.15 0.04 0
      name "left_light"
      lookupTable [
        0 0 0
        0.2 65535 0
      ]
    }
    DEF right DistanceSensor {
      translation 0.1 0.04 0.1
      rotation 0 1 0 -0.9162996938995747
      name "right_light"
      lookupTable [
        0 0 0
        0.2 65535 0
      ]
    }
    DEF Post Transform {
      translation 0 0.21 0
      children [
        Transform {
          children [
            Shape {
              appearance PBRAppearance {
                baseColor 0.8 0 0
                roughness 1
              }
              geometry Cylinder {
                height 0.2
                radius 0.03
              }
            }
            DEF Gun HingeJoint {
              jointParameters HingeJointParameters {
                position 239.99280014748027
                axis 0 1 0
              }
              device [
                RotationalMotor {
                  name "motor_4"
                }
              ]
              endPoint Solid {
                rotation 0 1 0 1.2317584746559809
                children [
                  DEF Gun Transform {
                    translation 0.05 0.05 0
                    rotation 0 0 1 1.5708
                    children [
                      Shape {
                        appearance PBRAppearance {
                          baseColor 0 0 0
                        }
                        geometry DEF sensor Cylinder {
                          height 0.05
                          radius 0.02
                        }
                      }
                    ]
                  }
                  DistanceSensor {
                    name "se"
                  }
                ]
                name "1"
                boundingObject USE Gun
                physics Physics {
                }
                linearVelocity 0.42394207058211375 -0.021213774261806165 0.12962036600909452
                angularVelocity -0.3028663857488698 0.6273321400466507 -0.2273484433616484
              }
            }
            DEF Radar HingeJoint {
              jointParameters HingeJointParameters {
                position 25.755983774638654
                axis 0 1 0
              }
              device [
                RotationalMotor {
                  name "motor_5"
                }
              ]
              endPoint Solid {
                rotation 0 1 0 0.6232425459203085
                children [
                  DEF Radar Transform {
                    translation 0.05 0 0
                    rotation 0 0 1 1.5708
                    children [
                      Shape {
                        appearance PBRAppearance {
                          baseColor 0.9294117647058824 0.8313725490196079 0
                        }
                        geometry USE sensor
                      }
                    ]
                  }
                ]
                name "other"
                boundingObject USE Radar
                physics Physics {
                }
                linearVelocity 0.42503186302665963 -0.02012798354002883 0.12961124625272663
                angularVelocity -0.3028666886520558 0.6273318869624477 -0.22734867054648977
              }
            }
          ]
        }
      ]
    }
  ]
  name "robot(1)"
  boundingObject USE BODY_TRANS
  physics Physics {
  }
  controller "u3_real_exam"
  linearVelocity 0.4022197638334038 -0.0025821767784277756 0.20476882343500355
  angularVelocity -0.30286673576516243 0.6273314332088804 -0.22734876211088917
}
DEF wall Solid {
  translation 3.2499999999999996 0.6 -2.3600000000000003
  rotation 0 1 0 6.021385901
  children [
    DEF wall Shape {
      appearance PBRAppearance {
      }
      geometry Box {
        size 2.9 1.2000000000000002 0.30000000000000004
      }
    }
  ]
  name "solid(1)"
  boundingObject USE wall
}
DEF wall Solid {
  translation 0.19738897345219494 0.6000000811296518 -1.8631439639103151
  rotation -0.2588190443306021 7.1923452487111625e-09 -0.9659258264959034 3.141592678504807
  children [
    DEF wall Shape {
      appearance PBRAppearance {
      }
      geometry Box {
        size 2.9 1.2000000000000002 0.30000000000000004
      }
    }
  ]
  name "solid(3)"
  boundingObject USE wall
}
DEF wall Solid {
  translation 2.147430792230632 0.6 1.754843999725728
  rotation -6.787767695857421e-08 0.9999999999999972 -2.81158549076604e-08 0.2617993678204156
  children [
    DEF wall Shape {
      appearance PBRAppearance {
      }
      geometry Box {
        size 2.9 1.2000000000000002 0.30000000000000004
      }
    }
  ]
  name "solid(2)"
  boundingObject USE wall
}
DEF wall Solid {
  translation 4.214887571329155 0.599999954113144 -0.16806433571955157
  rotation -1.356201641076181e-08 0.9999999999999999 -1.3562016558692992e-08 1.0471975288204154
  children [
    DEF wall Shape {
      appearance PBRAppearance {
      }
      geometry Box {
        size 2.9 1.2000000000000002 0.30000000000000004
      }
    }
  ]
  name "solid(6)"
  boundingObject USE wall
}
DEF wall Solid {
  translation -1.2719466511375728 0.600000033947869 2.6710633510738164
  rotation -6.787767695857421e-08 0.9999999999999972 -2.81158549076604e-08 0.2617993678204156
  children [
    DEF wall Shape {
      appearance PBRAppearance {
      }
      geometry Box {
        size 2.9 1.2000000000000002 0.30000000000000004
      }
    }
  ]
  name "solid(4)"
  boundingObject USE wall
}
DEF wall Solid {
  translation -3.181674765827451 0.6000000054288959 0.6199554568717361
  rotation -9.589793718731934e-09 0.9999999999999999 -1.2497662625355229e-08 1.3089969158204156
  children [
    DEF wall Shape {
      appearance PBRAppearance {
      }
      geometry Box {
        size 2.9 1.2000000000000002 0.30000000000000004
      }
    }
  ]
  name "solid(5)"
  boundingObject USE wall
}
